Workbook

Sheet All
A1: Tutor Name | B1: Tutor ID | C1: Stage | D1: Subject | E1: Status | F1: HR ID | G1: Stage Range | H1: Email | I1: Mobile Number | J1: Active
A2: إيمان محمود | B2: =VLOOKUP(A2,Tutors!A:B,2,0) -> 137198142829 | C2: Lower Primary | D2: Discover | E2: Backup | F2: =VLOOKUP(A2,Tutors!C:D,2,0) -> 1840 | G2: =VLOOKUP(A2,Tutors!C:E,3,0) -> EG04-EG05-EG06 | H2: =VLOOKUP(A2,Tutors!A:F,6,0) -> imaneabada@gmail.com | I2: =VLOOKUP(A2,Tutors!C:G,5,0) -> 01005729272 | J2: =COUNTIFS(Active!C:C,A2) -> 0
A3: نسرين زهران | B3: =VLOOKUP(A3,Tutors!A:B,2,0) -> 193156013197 | C3: Lower Primary | D3: Discover | E3: Active | F3: =VLOOKUP(A3,Tutors!C:D,2,0) -> 2172 | G3: =VLOOKUP(A3,Tutors!C:E,3,0) -> EG01-EG02-EG03 | H3: =VLOOKUP(A3,Tutors!A:F,6,0) -> the.peace20006@gmail.com | I3: =VLOOKUP(A3,Tutors!C:G,5,0) -> 01067579926 | J3: =COUNTIFS(Active!C:C,A3) -> 1
A4: رحاب حمدي | B4: =VLOOKUP(A4,Tutors!A:B,2,0) -> 838198456425 | C4: Lower Primary | D4: Discover | E4: Active | F4: =VLOOKUP(A4,Tutors!C:D,2,0) -> 2171 | G4: =VLOOKUP(A4,Tutors!C:E,3,0) -> EG01-EG02-EG03 | H4: =VLOOKUP(A4,Tutors!A:F,6,0) -> rehab533@gmail.com | I4: =VLOOKUP(A4,Tutors!C:G,5,0) -> 01019577994 | J4: =COUNTIFS(Active!C:C,A4) -> 1
A5: نرمين جلال | B5: =VLOOKUP(A5,Tutors!A:B,2,0) -> 209148542918 | C5: Lower Primary | D5: Discover | E5: Active | F5: =VLOOKUP(A5,Tutors!C:D,2,0) -> 2191 | G5: =VLOOKUP(A5,Tutors!C:E,3,0) -> EG01-EG02-EG03-EG04-EG05 | H5: =VLOOKUP(A5,Tutors!A:F,6,0) -> norenosman11@yahoo.com | I5: =VLOOKUP(A5,Tutors!C:G,5,0) -> 01285292060 | J5: =COUNTIFS(Active!C:C,A5) -> 1
A6: ندى عبد النبي | B6: =VLOOKUP(A6,Tutors!A:B,2,0) -> 105150134960 | C6: Lower Primary | D6: Discover | E6: Active | F6: =VLOOKUP(A6,Tutors!C:D,2,0) -> 2212 | G6: =VLOOKUP(A6,Tutors!C:E,3,0) -> EG01-EG02-EG03 | H6: =VLOOKUP(A6,Tutors!A:F,6,0) -> nadalisaid46@gmail.com | I6: =VLOOKUP(A6,Tutors!C:G,5,0) -> 01273190435 | J6: =COUNTIFS(Active!C:C,A6) -> 1
A7: مروة مجدي | B7: =VLOOKUP(A7,Tutors!A:B,2,0) -> 189108478931 | C7: Lower Primary | D7: Discover | E7: Active | F7: =VLOOKUP(A7,Tutors!C:D,2,0) -> 2443 | G7: =VLOOKUP(A7,Tutors!C:E,3,0) -> EG01-EG02-EG03 | H7: =VLOOKUP(A7,Tutors!A:F,6,0) -> jodyy2007@gmail.com | I7: =VLOOKUP(A7,Tutors!C:G,5,0) -> 01091927577 | J7: =COUNTIFS(Active!C:C,A7) -> 1
A8: يارا سلطان | B8: =VLOOKUP(A8,Tutors!A:B,2,0) -> 919170561064 | C8: Lower Primary | D8: Discover | E8: Active | F8: =VLOOKUP(A8,Tutors!C:D,2,0) -> 2561 | G8: =VLOOKUP(A8,Tutors!C:E,3,0) -> EG01-EG02-EG03 | H8: =VLOOKUP(A8,Tutors!A:F,6,0) -> ywael044@gmail.com | I8: =VLOOKUP(A8,Tutors!C:G,5,0) -> 01271833101 | J8: =COUNTIFS(Active!C:C,A8) -> 1
A9: أسماء الحسيني | B9: =VLOOKUP(A9,Tutors!A:B,2,0) -> 623157516497 | C9: Lower Primary | D9: Discover | E9: Active | F9: =VLOOKUP(A9,Tutors!C:D,2,0) -> 2580 | G9: =VLOOKUP(A9,Tutors!C:E,3,0) -> EG01-EG02-EG03 | H9: =VLOOKUP(A9,Tutors!A:F,6,0) -> elhosseinyasmaa@gmail.com | I9: =VLOOKUP(A9,Tutors!C:G,5,0) -> 01006995563 | J9: =COUNTIFS(Active!C:C,A9) -> 1
A10: دعاء مصطفى | B10: =VLOOKUP(A10,Tutors!A:B,2,0) -> 634163474745 | C10: Lower Primary | D10: Discover | E10: Active | F10: =VLOOKUP(A10,Tutors!C:D,2,0) -> 2722 | G10: =VLOOKUP(A10,Tutors!C:E,3,0) -> EG01-EG02-EG03-EG04-EG05-EG06 | H10: =VLOOKUP(A10,Tutors!A:F,6,0) -> doaamostafaalis@gmail.com | I10: =VLOOKUP(A10,Tutors!C:G,5,0) -> 01012291825 | J10: =COUNTIFS(Active!C:C,A10) -> 1
A11: مونيكا إدوارد | B11: =VLOOKUP(A11,Tutors!A:B,2,0) -> 194190610534 | C11: Lower Primary | D11: Discover | E11: Backup | F11: =VLOOKUP(A11,Tutors!C:D,2,0) -> 2757 | G11: =VLOOKUP(A11,Tutors!C:E,3,0) -> EG01-EG02-EG03-EG04 | H11: =VLOOKUP(A11,Tutors!A:F,6,0) -> moneyedward37@gmail.com | I11: =VLOOKUP(A11,Tutors!C:G,5,0) -> 01277626560 | J11: =COUNTIFS(Active!C:C,A11) -> 0
A12: دنيا فاروق | B12: =VLOOKUP(A12,Tutors!A:B,2,0) -> 148126371346 | C12: Lower Primary | D12: Discover | E12: Backup | F12: =VLOOKUP(A12,Tutors!C:D,2,0) -> 2745 | G12: =VLOOKUP(A12,Tutors!C:E,3,0) -> EG01-EG02-EG03 | H12: =VLOOKUP(A12,Tutors!A:F,6,0) -> doniafarouk2811@gmail.com | I12: =VLOOKUP(A12,Tutors!C:G,5,0) -> 01201302647 | J12: =COUNTIFS(Active!C:C,A12) -> 0
A13: إيريني عاطف | B13: =VLOOKUP(A13,Tutors!A:B,2,0) -> 530189784630 | C13: Lower Primary | D13: English | E13: Active | F13: =VLOOKUP(A13,Tutors!C:D,2,0) -> 2003 | G13: =VLOOKUP(A13,Tutors!C:E,3,0) -> EG01-EG02-EG03-EG04-EG05 | H13: =VLOOKUP(A13,Tutors!A:F,6,0) -> erineyatef@gmail.com | I13: =VLOOKUP(A13,Tutors!C:G,5,0) -> 01211816220 | J13: =COUNTIFS(Active!C:C,A13) -> 1
A14: هبة عبد الحميد | B14: =VLOOKUP(A14,Tutors!A:B,2,0) -> 603187625747 | C14: Lower Primary | D14: English | E14: Active | F14: =VLOOKUP(A14,Tutors!C:D,2,0) -> 2103 | G14: =VLOOKUP(A14,Tutors!C:E,3,0) | H14: =VLOOKUP(A14,Tutors!A:F,6,0) -> heba.abdelhameed99@gmail.com | I14: =VLOOKUP(A14,Tutors!C:G,5,0) -> 01126571109 | J14: =COUNTIFS(Active!C:C,A14) -> 1
A15: مها عبد الله | B15: =VLOOKUP(A15,Tutors!A:B,2,0) -> 865121843486 | C15: Lower Primary | D15: English | E15: Active | F15: 2244 | G15: =VLOOKUP(A15,Tutors!C:E,3,0) | H15: =VLOOKUP(A15,Tutors!A:F,6,0) -> mahahimony@gmail.com | I15: =VLOOKUP(A15,Tutors!C:G,5,0) -> 01156615561 | J15: =COUNTIFS(Active!C:C,A15) -> 1
A16: ميرا هشام | B16: =VLOOKUP(A16,Tutors!A:B,2,0) -> 758108752769 | C16: Lower Primary | D16: English | E16: Active | F16: =VLOOKUP(A16,Tutors!C:D,2,0) -> 2337 | G16: =VLOOKUP(A16,Tutors!C:E,3,0) | H16: =VLOOKUP(A16,Tutors!A:F,6,0) -> merahesham2000@gmail.com | I16: =VLOOKUP(A16,Tutors!C:G,5,0) -> 01027391210 | J16: =COUNTIFS(Active!C:C,A16) -> 1
A17: نوران أسامة | B17: =VLOOKUP(A17,Tutors!A:B,2,0) -> 426167021594 | C17: Lower Primary | D17: English | E17: Active | F17: =VLOOKUP(A17,Tutors!C:D,2,0) -> 2519 | G17: =VLOOKUP(A17,Tutors!C:E,3,0) -> EG01-EG02-EG03-EG04 | H17: =VLOOKUP(A17,Tutors!A:F,6,0) -> nouranyl64@gmail.com | I17: =VLOOKUP(A17,Tutors!C:G,5,0) -> 01010594459 | J17: =COUNTIFS(Active!C:C,A17) -> 1
A18: إسراء علاء | B18: =VLOOKUP(A18,Tutors!A:B,2,0) -> 915139613231 | C18: Lower Primary | D18: English | E18: Backup | F18: =VLOOKUP(A18,Tutors!C:D,2,0) -> 2422 | G18: =VLOOKUP(A18,Tutors!C:E,3,0) -> EG01-EG02-EG03-EG04-EG05-EG06-EG07 | H18: =VLOOKUP(A18,Tutors!A:F,6,0) -> esraalaa25@gmail.com | I18: =VLOOKUP(A18,Tutors!C:G,5,0) -> 01091311114 | J18: =COUNTIFS(Active!C:C,A18) -> 0
A19: سارة جرجس | B19: =VLOOKUP(A19,Tutors!A:B,2,0) -> 598135839671 | C19: Lower Primary | D19: English | E19: Active | F19: =VLOOKUP(A19,Tutors!C:D,2,0) -> 2493 | G19: =VLOOKUP(A19,Tutors!C:E,3,0) -> EG01-EG02-EG03-EG04-EG05 | H19: =VLOOKUP(A19,Tutors!A:F,6,0) -> aueed.eteachers@gmail.com | I19: =VLOOKUP(A19,Tutors!C:G,5,0) -> 01270819064 | J19: =COUNTIFS(Active!C:C,A19) -> 1
A20: ندى شريف | B20: =VLOOKUP(A20,Tutors!A:B,2,0) -> 695139708380 | C20: Lower Primary | D20: English | E20: Active | F20: =VLOOKUP(A20,Tutors!C:D,2,0) -> 2614 | G20: =VLOOKUP(A20,Tutors!C:E,3,0) -> EG01-EG02-EG03-EG04-EG05 | H20: =VLOOKUP(A20,Tutors!A:F,6,0) -> nadasherif1007@gmail.com | I20: =VLOOKUP(A20,Tutors!C:G,5,0) | J20: =COUNTIFS(Active!C:C,A20) -> 1
A21: أسماء حمزة | B21: =VLOOKUP(A21,Tutors!A:B,2,0) -> 967160462696 | C21: Lower Primary | D21: English | E21: Active | F21: =VLOOKUP(A21,Tutors!C:D,2,0) -> 2643 | G21: =VLOOKUP(A21,Tutors!C:E,3,0) -> EG01-EG02 | H21: =VLOOKUP(A21,Tutors!A:F,6,0) -> somahamza27@gmail.com | I21: =VLOOKUP(A21,Tutors!C:G,5,0) | J21: =COUNTIFS(Active!C:C,A21) -> 1
A22: شاهندة عبد العزيز | B22: =VLOOKUP(A22,Tutors!A:B,2,0) -> 135178965350 | C22: Lower Primary | D22: English | E22: Inactive | F22: =VLOOKUP(A22,Tutors!C:D,2,0) -> 2642 | G22: =VLOOKUP(A22,Tutors!C:E,3,0) -> EG01-EG02 | H22: =VLOOKUP(A22,Tutors!A:F,6,0) -> shahendaabdulaziz98@gmail.com | I22: =VLOOKUP(A22,Tutors!C:G,5,0) -> 01004298923 | J22: =COUNTIFS(Active!C:C,A22) -> 0
A23: جيهان سمير | B23: =VLOOKUP(A23,Tutors!A:B,2,0) -> 930131871381 | C23: Lower Primary | D23: English | E23: Active | F23: =VLOOKUP(A23,Tutors!C:D,2,0) -> 2715 | G23: =VLOOKUP(A23,Tutors!C:E,3,0) -> EG01-EG02-EG03-EG04-5 | H23: =VLOOKUP(A23,Tutors!A:F,6,0) -> mrsgehan94@gmail.com | I23: =VLOOKUP(A23,Tutors!C:G,5,0) -> 1013586544 | J23: =COUNTIFS(Active!C:C,A23) -> 1
A24: ريهام هريدي | B24: =VLOOKUP(A24,Tutors!A:B,2,0) -> 208148393089 | C24: Lower Primary | D24: English | E24: Active | F24: =VLOOKUP(A24,Tutors!C:D,2,0) -> 2695 | G24: =VLOOKUP(A24,Tutors!C:E,3,0) -> EG01-EG02 | H24: =VLOOKUP(A24,Tutors!A:F,6,0) -> reham.haridy17@gmail.com | I24: =VLOOKUP(A24,Tutors!C:G,5,0) -> 01126620688 | J24: =COUNTIFS(Active!C:C,A24) -> 1
A25: ندى علي | B25: =VLOOKUP(A25,Tutors!A:B,2,0) -> 406159296081 | C25: Lower Primary | D25: English | E25: Active | F25: =VLOOKUP(A25,Tutors!C:D,2,0) -> 2730 | G25: =VLOOKUP(A25,Tutors!C:E,3,0) -> EG01-EG02-EG03-EG04 | H25: =VLOOKUP(A25,Tutors!A:F,6,0) -> nadaaly58@gmail.com | I25: =VLOOKUP(A25,Tutors!C:G,5,0) -> 01275735695 | J25: =COUNTIFS(Active!C:C,A25) -> 1
A26: مارينا عماد | B26: =VLOOKUP(A26,Tutors!A:B,2,0) -> 586170564150 | C26: Lower Primary | D26: English | E26: Active | F26: =VLOOKUP(A26,Tutors!C:D,2,0) -> 2629 | G26: =VLOOKUP(A26,Tutors!C:E,3,0) -> EG01-EG02-EG03-EG04 | H26: =VLOOKUP(A26,Tutors!A:F,6,0) -> marinaemad4922@gmail.com | I26: =VLOOKUP(A26,Tutors!C:G,5,0) -> 01210882072 | J26: =COUNTIFS(Active!C:C,A26) -> 1
A27: ماريام أشرف | B27: =VLOOKUP(A27,Tutors!A:B,2,0) -> 450190591429 | C27: Lower Primary | D27: English | E27: Active | F27: =VLOOKUP(A27,Tutors!C:D,2,0) -> 2781 | G27: =VLOOKUP(A27,Tutors!C:E,3,0) -> EG01-EG02-EG03-EG04 | H27: =VLOOKUP(A27,Tutors!A:F,6,0) -> ashrfmaryam557@gmail.com | I27: =VLOOKUP(A27,Tutors!C:G,5,0) | J27: =COUNTIFS(Active!C:C,A27) -> 1
... A55: دعاء زكريا | B55: =VLOOKUP(A55,Tutors!A:B,2,0) -> 689140818514 | C55: Lower Primary | D55: اللغة العربية | E55: Active | F55: =VLOOKUP(A55,Tutors!C:D,2,0) -> 2278 | G55: =VLOOKUP(A55,Tutors!C:E,3,0) -> EG01-EG02-EG03-EG04-EG05-EG06 | H55: =VLOOKUP(A55,Tutors!A:F,6,0) -> douaazika@gmail.com | I55: =VLOOKUP(A55,Tutors!C:G,5,0) | J55: =COUNTIFS(Active!C:C,A55) -> 1
A56: ياسمين محمد | B56: =VLOOKUP(A56,Tutors!A:B,2,0) -> 948108182631 | C56: Lower Primary | D56: اللغة العربية | E56: Active | F56: =VLOOKUP(A56,Tutors!C:D,2,0) -> 2321 | G56: EG01-EG02-EG03 | H56: =VLOOKUP(A56,Tutors!A:F,6,0) -> myasmine116@gmail.com | I56: =VLOOKUP(A56,Tutors!C:G,5,0) -> 01015633019 | J56: =COUNTIFS(Active!C:C,A56) -> 0
A57: إنجي مختار | B57: =VLOOKUP(A57,Tutors!A:B,2,0) -> 215195154738 | C57: Lower Primary | D57: اللغة العربية | E57: Active | F57: =VLOOKUP(A57,Tutors!C:D,2,0) -> 2441 | G57: =VLOOKUP(A57,Tutors!C:E,3,0) -> EG01-EG02-EG03 | H57: =VLOOKUP(A57,Tutors!A:F,6,0) -> enjymokhtar.219@gmail.com | I57: =VLOOKUP(A57,Tutors!C:G,5,0) -> 01201521125 | J57: =COUNTIFS(Active!C:C,A57) -> 1
A58: شيماء كمال | B58: =VLOOKUP(A58,Tutors!A:B,2,0) -> 257176871480 | C58: Lower Primary | D58: اللغة العربية | E58: Active | F58: =VLOOKUP(A58,Tutors!C:D,2,0) -> 2461 | G58: =VLOOKUP(A58,Tutors!C:E,3,0) -> EG01-EG02-EG03 | H58: =VLOOKUP(A58,Tutors!A:F,6,0) -> shimaakamal553@gmail.com | I58: =VLOOKUP(A58,Tutors!C:G,5,0) -> 01157711782 | J58: =COUNTIFS(Active!C:C,A58) -> 1
A59: أسماء قاسم | B59: =VLOOKUP(A59,Tutors!A:B,2,0) -> 183129070275 | C59: Lower Primary | D59: اللغة العربية | E59: Active | F59: =VLOOKUP(A59,Tutors!C:D,2,0) -> 2458 | G59: =VLOOKUP(A59,Tutors!C:E,3,0) -> EG01-EG02-EG03 | H59: =VLOOKUP(A59,Tutors!A:F,6,0) -> asmaakasem25@hotmail.com | I59: =VLOOKUP(A59,Tutors!C:G,5,0) -> 01100109067 | J59: =COUNTIFS(Active!C:C,A59) -> 1
A60: شيماء حسين فهمي | B60: =VLOOKUP(A60,Tutors!A:B,2,0) -> 573149872824 | C60: Lower Primary | D60: اللغة العربية | E60: Active | F60: =VLOOKUP(A60,Tutors!C:D,2,0) -> 2491 | G60: =VLOOKUP(A60,Tutors!C:E,3,0) -> EG01-EG02-EG03 | H60: =VLOOKUP(A60,Tutors!A:F,6,0) -> shimaahussain2@gmail.com | I60: =VLOOKUP(A60,Tutors!C:G,5,0) -> 01016634509 | J60: =COUNTIFS(Active!C:C,A60) -> 1
A61: منال إبراهيم | B61: =VLOOKUP(A61,Tutors!A:B,2,0) -> 974169434219 | C61: Lower Primary | D61: اللغة العربية | E61: Active | F61: =VLOOKUP(A61,Tutors!C:D,2,0) -> 2448 | G61: =VLOOKUP(A61,Tutors!C:E,3,0) -> EG01-EG02-EG03 | H61: =VLOOKUP(A61,Tutors!A:F,6,0) -> manalabdelnaby10@gmail.com | I61: =VLOOKUP(A61,Tutors!C:G,5,0) | J61: =COUNTIFS(Active!C:C,A61) -> 1
A62: شيماء سليمان | B62: =VLOOKUP(A62,Tutors!A:B,2,0) -> 574161321575 | C62: Lower Primary | D62: اللغة العربية | E62: Active | F62: =VLOOKUP(A62,Tutors!C:D,2,0) -> 2581 | G62: =VLOOKUP(A62,Tutors!C:E,3,0) -> EG01-EG02-EG03 | H62: =VLOOKUP(A62,Tutors!A:F,6,0) -> shimosoliman4016@gmail.com | I62: =VLOOKUP(A62,Tutors!C:G,5,0) | J62: =COUNTIFS(Active!C:C,A62) -> 1
A63: أماني سعد | B63: =VLOOKUP(A63,Tutors!A:B,2,0) -> 879135754897 | C63: Lower Primary | D63: اللغة العربية | E63: Active | F63: =VLOOKUP(A63,Tutors!C:D,2,0) -> 2619 | G63: =VLOOKUP(A63,Tutors!C:E,3,0) -> EG01-EG02-EG03 | H63: =VLOOKUP(A63,Tutors!A:F,6,0) -> amanianas217@gmail.com | I63: =VLOOKUP(A63,Tutors!C:G,5,0) -> 01001014795 | J63: =COUNTIFS(Active!C:C,A63) -> 1
A64: آلاء أشرف | B64: =VLOOKUP(A64,Tutors!A:B,2,0) -> 865163793520 | C64: Lower Primary | D64: اللغة العربية | E64: Active | F64: =VLOOKUP(A64,Tutors!C:D,2,0) -> 2703 | G64: =VLOOKUP(A64,Tutors!C:E,3,0) -> EG01-EG02-EG03-EG04 | H64: =VLOOKUP(A64,Tutors!A:F,6,0) -> alaa.work91@gmail.com | I64: =VLOOKUP(A64,Tutors!C:G,5,0) -> 1006108593 | J64: =COUNTIFS(Active!C:C,A64) -> 1
A65: سارة سعيد | B65: =VLOOKUP(A65,Tutors!A:B,2,0) -> 923168406232 | C65: Lower Primary | D65: اللغة العربية | E65: Active | F65: =VLOOKUP(A65,Tutors!C:D,2,0) -> 2735 | G65: =VLOOKUP(A65,Tutors!C:E,3,0) -> EG01-EG02-EG03-EG04-EG05-EG06 | H65: =VLOOKUP(A65,Tutors!A:F,6,0) -> sosajojo29@gmail.com | I65: =VLOOKUP(A65,Tutors!C:G,5,0) -> 01211339318 | J65: =COUNTIFS(Active!C:C,A65) -> 1
A66: زينب سمير | B66: =VLOOKUP(A66,Tutors!A:B,2,0) -> 762178172726 | C66: Lower Primary | D66: اللغة العربية | E66: Active | F66: =VLOOKUP(A66,Tutors!C:D,2,0) -> 2720 | G66: =VLOOKUP(A66,Tutors!C:E,3,0) -> EG01-EG02-EG03-EG04-EG05-EG06 | H66: =VLOOKUP(A66,Tutors!A:F,6,0) -> zeinabsamirsamir@gmail.com | I66: =VLOOKUP(A66,Tutors!C:G,5,0) | J66: =COUNTIFS(Active!C:C,A66) -> 0
A67: أميرة غيث | B67: =VLOOKUP(A67,Tutors!A:B,2,0) -> 962134062378 | C67: Higher Primary | D67: English | E67: Active | F67: =VLOOKUP(A67,Tutors!C:D,2,0) -> 1963 | G67: =VLOOKUP(A67,Tutors!C:E,3,0) | H67: =VLOOKUP(A67,Tutors!A:F,6,0) -> amiraghth@gmail.com | I67: =VLOOKUP(A67,Tutors!C:G,5,0) -> 01119682313 | J67: =COUNTIFS(Active!C:C,A67) -> 1
...

Sheet Active
A1: Tutor Name | C1: {=UNIQUE(A:A)} -> Tutor Name
A2: محمد لقمان | C2: محمد لقمان
A3: محمد لقمان | C3: إيمان دسوقي
A4: محمد لقمان | C4: ندى عبد النبي
A5: محمد لقمان | C5: حنان صبحي
A6: إيمان دسوقي | C6: رنا طارق
A7: إيمان دسوقي | C7: نرمين صبري
A8: ندى عبد النبي | C8: أحمد عاطف
A9: إيمان دسوقي | C9: أحمد سيف
A10: حنان صبحي | C10: إيمان رمضان
A11: رنا طارق | C11: الشيماء جمال
A12: نرمين صبري | C12: خلود محمد
A13: نرمين صبري | C13: أحمد حاتم
... A462: دعاء زكريا | C462: وائل سلطان
A463: عبد الله معين
A464: السيد سابق
A465: محمد جودة
A466: محمد جودة
A467: هبة محمد
A468: رانا سامي
A469: هبة محمد
A470: عبد الله معين
A471: عبد الله معين
A472: محمد جودة
A473: إيمان حسن
A474: إيمان حسن
... A1700: هويدا منصور

Sheet Data
A1: Tutor Name | B1: Tutor ID | C1: Stage | D1: Subject | E1: Status | F1: HR ID | G1: Stage Range | H1: Email | I1: Mobile Number
A2: إيمان محمود | B2: 137198142829 | C2: Lower Primary | D2: Discover | E2: Backup | F2: 1840 | G2: EG04-EG05-EG06 | H2: imaneabada@gmail.com | I2: 01005729272
A3: نسرين زهران | B3: 193156013197 | C3: Lower Primary | D3: Discover | E3: Active | F3: 2172 | G3: EG01-EG02-EG03 | H3: the.peace20006@gmail.com | I3: 01067579926
A4: رحاب حمدي | B4: 838198456425 | C4: Lower Primary | D4: Discover | E4: Active | F4: 2171 | G4: EG01-EG02-EG03 | H4: rehab533@gmail.com | I4: 01019577994
A5: نرمين جلال | B5: 209148542918 | C5: Lower Primary | D5: Discover | E5: Active | F5: 2191 | G5: EG01-EG02-EG03-EG04-EG05 | H5: norenosman11@yahoo.com | I5: 01285292060
A6: ندى عبد النبي | B6: 105150134960 | C6: Lower Primary | D6: Discover | E6: Active | F6: 2212 | G6: EG01-EG02-EG03 | H6: nadalisaid46@gmail.com | I6: 01273190435
A7: مروة مجدي | B7: 189108478931 | C7: Lower Primary | D7: Discover | E7: Active | F7: 2443 | G7: EG01-EG02-EG03 | H7: jodyy2007@gmail.com | I7: 01091927577
A8: يارا سلطان | B8: 919170561064 | C8: Lower Primary | D8: Discover | E8: Active | F8: 2561 | G8: EG01-EG02-EG03 | H8: ywael044@gmail.com | I8: 01271833101
A9: أسماء الحسيني | B9: 623157516497 | C9: Lower Primary | D9: Discover | E9: Active | F9: 2580 | G9: EG01-EG02-EG03 | H9: elhosseinyasmaa@gmail.com | I9: 01006995563
A10: دعاء مصطفى | B10: 634163474745 | C10: Lower Primary | D10: Discover | E10: Active | F10: 2722 | G10: EG01-EG02-EG03-EG04-EG05-EG06 | H10: doaamostafaalis@gmail.com | I10: 01012291825
A11: مونيكا إدوارد | B11: 194190610534 | C11: Lower Primary | D11: Discover | E11: Backup | F11: 2757 | G11: EG01-EG02-EG03-EG04 | H11: moneyedward37@gmail.com | I11: 01277626560
A12: دنيا فاروق | B12: 148126371346 | C12: Lower Primary | D12: Discover | E12: Backup | F12: 2745 | G12: EG01-EG02-EG03 | H12: doniafarouk2811@gmail.com | I12: 01201302647
A13: إيريني عاطف | B13: 530189784630 | C13: Lower Primary | D13: English | E13: Active | F13: 2003 | G13: EG01-EG02-EG03-EG04-EG05 | H13: erineyatef@gmail.com | I13: 01211816220
A14: هبة عبد الحميد | B14: 603187625747 | C14: Lower Primary | D14: English | E14: Active | F14: 2103 | H14: heba.abdelhameed99@gmail.com | I14: 01126571109
A15: مها عبد الله | B15: 865121843486 | C15: Lower Primary | D15: English | E15: Active | F15: 2244 | H15: mahahimony@gmail.com | I15: 01156615561
A16: ميرا هشام | B16: 758108752769 | C16: Lower Primary | D16: English | E16: Active | F16: 2337 | H16: merahesham2000@gmail.com | I16: 01027391210
A17: نوران أسامة | B17: 426167021594 | C17: Lower Primary | D17: English | E17: Active | F17: 2519 | G17: EG01-EG02-EG03-EG04 | H17: nouranyl64@gmail.com | I17: 01010594459
A18: إسراء علاء | B18: 915139613231 | C18: Lower Primary | D18: English | E18: Backup | F18: 2422 | G18: EG01-EG02-EG03-EG04-EG05-EG06-EG07 | H18: esraalaa25@gmail.com | I18: 01091311114
A19: سارة جرجس | B19: 598135839671 | C19: Lower Primary | D19: English | E19: Active | F19: 2493 | G19: EG01-EG02-EG03-EG04-EG05 | H19: aueed.eteachers@gmail.com | I19: 01270819064
A20: ندى شريف | B20: 695139708380 | C20: Lower Primary | D20: English | E20: Active | F20: 2614 | G20: EG01-EG02-EG03-EG04-EG05 | H20: nadasherif1007@gmail.com
A21: أسماء حمزة | B21: 967160462696 | C21: Lower Primary | D21: English | E21: Active | F21: 2643 | G21: EG01-EG02 | H21: somahamza27@gmail.com
A22: شاهندة عبد العزيز | B22: 135178965350 | C22: Lower Primary | D22: English | E22: Inactive | F22: 2642 | G22: EG01-EG02 | H22: shahendaabdulaziz98@gmail.com | I22: 01004298923
A23: جيهان سمير | B23: 930131871381 | C23: Lower Primary | D23: English | E23: Active | F23: 2715 | G23: EG01-EG02-EG03-EG04-5 | H23: mrsgehan94@gmail.com | I23: 1013586544
A24: ريهام هريدي | B24: 208148393089 | C24: Lower Primary | D24: English | E24: Active | F24: 2695 | G24: EG01-EG02 | H24: reham.haridy17@gmail.com | I24: 01126620688
A25: ندى علي | B25: 406159296081 | C25: Lower Primary | D25: English | E25: Active | F25: 2730 | G25: EG01-EG02-EG03-EG04 | H25: nadaaly58@gmail.com | I25: 01275735695
A26: مارينا عماد | B26: 586170564150 | C26: Lower Primary | D26: English | E26: Active | F26: 2629 | G26: EG01-EG02-EG03-EG04 | H26: marinaemad4922@gmail.com | I26: 01210882072
A27: ماريام أشرف | B27: 450190591429 | C27: Lower Primary | D27: English | E27: Active | F27: 2781 | G27: EG01-EG02-EG03-EG04 | H27: ashrfmaryam557@gmail.com
A28: إيمان جلال | B28: 618168909236 | C28: Lower Primary | D28: English | E28: Active | F28: 2784 | G28: EG01-EG02-EG03-EG04-EG05-EG06 | H28: galaleman21@yahoo.com | I28: 01276133970
A29: نهى لطفي | B29: 729171317072 | C29: Lower Primary | D29: English | E29: Active | F29: 2771 | G29: EG01-EG02-EG03-EG04-EG05-EG06 | H29: nohalotfy33@gmail.com | I29: 01271850094
A30: صفا عادل | B30: 898178084762 | C30: Lower Primary | D30: English | E30: Active | F30: 2783 | G30: EG01-EG02-EG03-EG04-EG05-EG06 | H30: safaadel499@gmail.com
A31: نجوى بدوي | B31: 193161234392 | C31: Lower Primary | D31: English | E31: Inactive | F31: 2779 | G31: EG01-EG02-EG03 | H31: nosamohamed000@gmail.com
A32: شاهنده محمد | B32: 439182479634 | C32: Lower Primary | D32: English | E32: Active | F32: 2807 | G32: EG01-EG02-EG03-EG04 | H32: shahendamohammad3@gmail.com | I32: 01223315390
A33: أسماء أشرف | B33: 363152838573 | C33: Lower Primary | D33: Mathematics | E33: Active | F33: 2310 | H33: asmaaashraf.aa@gmail.com | I33: 01015511375
A34: آية صبحي | B34: 628128564178 | C34: Lower Primary | D34: Mathematics | E34: Active | F34: 2290 | H34: ayasobhy2014@gmail.com | I34: 01096896433
A35: نورهان هاني | B35: 832181306187 | C35: Lower Primary | D35: Mathematics | E35: Active | F35: 2436 | G35: EG01-EG02-EG03-EG04-EG05-EG06 | H35: nourhan.hany.amer.1992@gmail.com | I35: 01023766623
A36: آية فتحي | B36: 617181867475 | C36: Lower Primary | D36: Mathematics | E36: Active | F36: 2428 | G36: EG01-EG02-EG03-EG04-EG05-EG06 | H36: ayafathy1020@gmail.com | I36: 01025755518//01507075518
A37: نورهان ياسر | B37: 957197456092 | C37: Lower Primary | D37: Mathematics | E37: Active | F37: 2427 | G37: EG01-EG02-EG03 | H37: nourhanyasser1999184@gmail.com | I37: 01110620513
A38: إيمان رمضان | B38: 896191427156 | C38: Lower Primary | D38: Mathematics | E38: Active | F38: 2440 | G38: EG01-EG02-EG03 | H38: emanali8134@gmail.com | I38: 01282166883
A39: آية عادل | B39: 304149687570 | C39: Lower Primary | D39: Mathematics | E39: Active | F39: 2454 | G39: EG01-EG02-EG03 | H39: aya963539@gmail.com | I39: 01064460758
A40: دينا رضوان | B40: 590135797239 | C40: Lower Primary | D40: Mathematics | E40: Active | F40: 2447 | G40: EG01-EG02-EG03-EG04-EG05 | H40: dinaradwan109@gmail.com | I40: 01144211463
...

Sheet Tutors
A1: =IFERROR(__xludf.DUMMYFUNCTION("IMPORTRANGE(""https://docs.google.com/spreadsheets/d/196Silsrf5-pGVgMAh12IsxqLLk10J-5WvEmb-v-qEgc/edit?pli=1&gid=91105518#gid=91105518"", ""Tutors Data!B:B"")"),"Tutor Name") -> Tutor Name | B1: =IFERROR(__xludf.DUMMYFUNCTION("IMPORTRANGE(""https://docs.google.com/spreadsheets/d/196Silsrf5-pGVgMAh12IsxqLLk10J-5WvEmb-v-qEgc/edit?pli=1&gid=91105518#gid=91105518"", ""Tutors Data!a:a"")"),"Tutor ID") -> Tutor ID | C1: =IFERROR(__xludf.DUMMYFUNCTION("IMPORTRANGE(""https://docs.google.com/spreadsheets/d/196Silsrf5-pGVgMAh12IsxqLLk10J-5WvEmb-v-qEgc/edit?pli=1&gid=91105518#gid=91105518"", ""Tutors Data!B:B"")"),"Tutor Name") -> Tutor Name | D1: =IFERROR(__xludf.DUMMYFUNCTION("IMPORTRANGE(""https://docs.google.com/spreadsheets/d/196Silsrf5-pGVgMAh12IsxqLLk10J-5WvEmb-v-qEgc/edit?pli=1&gid=91105518#gid=91105518"", ""Tutors Data!d:d"")"),"HR ID") -> HR ID | E1: =IFERROR(__xludf.DUMMYFUNCTION("IMPORTRANGE(""https://docs.google.com/spreadsheets/d/196Silsrf5-pGVgMAh12IsxqLLk10J-5WvEmb-v-qEgc/edit?pli=1&gid=91105518#gid=91105518"", ""Tutors Data!g:g"")"),"Stages") -> Stages | F1: =IFERROR(__xludf.DUMMYFUNCTION("IMPORTRANGE(""https://docs.google.com/spreadsheets/d/196Silsrf5-pGVgMAh12IsxqLLk10J-5WvEmb-v-qEgc/edit?pli=1&gid=91105518#gid=91105518"", ""Tutors Data!h:i"")"),"email") -> email | G1: =IFERROR(__xludf.DUMMYFUNCTION("""COMPUTED_VALUE"""),"Mobile Number") -> Mobile Number
A2: =IFERROR(__xludf.DUMMYFUNCTION("""COMPUTED_VALUE"""),"أحمد حاتم") -> أحمد حاتم | B2: =IFERROR(__xludf.DUMMYFUNCTION("""COMPUTED_VALUE"""),1.79169073012E11) -> 179169073012 | C2: =IFERROR(__xludf.DUMMYFUNCTION("""COMPUTED_VALUE"""),"أحمد حاتم") -> أحمد حاتم | D2: =IFERROR(__xludf.DUMMYFUNCTION("""COMPUTED_VALUE"""),"888") -> 888 | F2: =IFERROR(__xludf.DUMMYFUNCTION("""COMPUTED_VALUE"""),"ahmed.hatem@nagwa.com") -> ahmed.hatem@nagwa.com | G2: =IFERROR(__xludf.DUMMYFUNCTION("""COMPUTED_VALUE"""),2.01156629949E11) -> 201156629949
A3: =IFERROR(__xludf.DUMMYFUNCTION("""COMPUTED_VALUE"""),"مازن جاد") -> مازن جاد | B3: =IFERROR(__xludf.DUMMYFUNCTION("""COMPUTED_VALUE"""),4.52123973904E11) -> 452123973904 | C3: =IFERROR(__xludf.DUMMYFUNCTION("""COMPUTED_VALUE"""),"مازن جاد") -> مازن جاد | D3: =IFERROR(__xludf.DUMMYFUNCTION("""COMPUTED_VALUE"""),"1330") -> 1330 | F3: =IFERROR(__xludf.DUMMYFUNCTION("""COMPUTED_VALUE"""),"s-mazenhafez@zewailcity.edu.eg") -> s-mazenhafez@zewailcity.edu.eg
A4: =IFERROR(__xludf.DUMMYFUNCTION("""COMPUTED_VALUE"""),"ربيع الدوحة") -> ربيع الدوحة | B4: =IFERROR(__xludf.DUMMYFUNCTION("""COMPUTED_VALUE"""),6.5617963685E11) -> 656179636850 | C4: =IFERROR(__xludf.DUMMYFUNCTION("""COMPUTED_VALUE"""),"ربيع الدوحة") -> ربيع الدوحة | D4: =IFERROR(__xludf.DUMMYFUNCTION("""COMPUTED_VALUE"""),"110") -> 110 | E4: =IFERROR(__xludf.DUMMYFUNCTION("""COMPUTED_VALUE"""),"EG07-EG08-EG09-EG10-EG11-EG12") -> EG07-EG08-EG09-EG10-EG11-EG12 | F4: =IFERROR(__xludf.DUMMYFUNCTION("""COMPUTED_VALUE"""),"rabeeelshaer1@gmail.com") -> rabeeelshaer1@gmail.com
A5: =IFERROR(__xludf.DUMMYFUNCTION("""COMPUTED_VALUE"""),"رضا جبريل") -> رضا جبريل | B5: =IFERROR(__xludf.DUMMYFUNCTION("""COMPUTED_VALUE"""),1.98159430149E11) -> 198159430149 | C5: =IFERROR(__xludf.DUMMYFUNCTION("""COMPUTED_VALUE"""),"رضا جبريل") -> رضا جبريل | D5: =IFERROR(__xludf.DUMMYFUNCTION("""COMPUTED_VALUE"""),"1083") -> 1083 | E5: =IFERROR(__xludf.DUMMYFUNCTION("""COMPUTED_VALUE"""),"EG10-EG11-EG12") -> EG10-EG11-EG12
A6: =IFERROR(__xludf.DUMMYFUNCTION("""COMPUTED_VALUE"""),"عبير فؤاد") -> عبير فؤاد | B6: =IFERROR(__xludf.DUMMYFUNCTION("""COMPUTED_VALUE"""),8.93170457017E11) -> 893170457017 | C6: =IFERROR(__xludf.DUMMYFUNCTION("""COMPUTED_VALUE"""),"عبير فؤاد") -> عبير فؤاد | D6: =IFERROR(__xludf.DUMMYFUNCTION("""COMPUTED_VALUE"""),"1245") -> 1245 | F6: =IFERROR(__xludf.DUMMYFUNCTION("""COMPUTED_VALUE"""),"abeer.fouad@nagwa.com") -> abeer.fouad@nagwa.com | G6: =IFERROR(__xludf.DUMMYFUNCTION("""COMPUTED_VALUE"""),2.01090406534E11) -> 201090406534
A7: =IFERROR(__xludf.DUMMYFUNCTION("""COMPUTED_VALUE"""),"عبد الله معين") -> عبد الله معين | B7: =IFERROR(__xludf.DUMMYFUNCTION("""COMPUTED_VALUE"""),1.30151805637E11) -> 130151805637 | C7: =IFERROR(__xludf.DUMMYFUNCTION("""COMPUTED_VALUE"""),"عبد الله معين") -> عبد الله معين | D7: =IFERROR(__xludf.DUMMYFUNCTION("""COMPUTED_VALUE"""),"145") -> 145 | E7: =IFERROR(__xludf.DUMMYFUNCTION("""COMPUTED_VALUE"""),"EG04-EG05-EG06-EG07-EG08-EG09-EG10-EG11-EG12") -> EG04-EG05-EG06-EG07-EG08-EG09-EG10-EG11-EG12 | F7: =IFERROR(__xludf.DUMMYFUNCTION("""COMPUTED_VALUE"""),"abdallah.moeenn@gmail.com") -> abdallah.moeenn@gmail.com
A8: =IFERROR(__xludf.DUMMYFUNCTION("""COMPUTED_VALUE"""),"محمد البدساوي") -> محمد البدساوي | B8: =IFERROR(__xludf.DUMMYFUNCTION("""COMPUTED_VALUE"""),1.43165762069E11) -> 143165762069 | C8: =IFERROR(__xludf.DUMMYFUNCTION("""COMPUTED_VALUE"""),"محمد البدساوي") -> محمد البدساوي | D8: =IFERROR(__xludf.DUMMYFUNCTION("""COMPUTED_VALUE"""),"737") -> 737 | E8: =IFERROR(__xludf.DUMMYFUNCTION("""COMPUTED_VALUE"""),"EG04-EG05-EG06-EG07-EG08-EG09-EG10-EG11-EG12") -> EG04-EG05-EG06-EG07-EG08-EG09-EG10-EG11-EG12 | F8: =IFERROR(__xludf.DUMMYFUNCTION("""COMPUTED_VALUE"""),"mohamed.eid@nagwa.com") -> mohamed.eid@nagwa.com
A9: =IFERROR(__xludf.DUMMYFUNCTION("""COMPUTED_VALUE"""),"محمد إسماعيل") -> محمد إسماعيل | B9: =IFERROR(__xludf.DUMMYFUNCTION("""COMPUTED_VALUE"""),9.06184953437E11) -> 906184953437 | C9: =IFERROR(__xludf.DUMMYFUNCTION("""COMPUTED_VALUE"""),"محمد إسماعيل") -> محمد إسماعيل | D9: =IFERROR(__xludf.DUMMYFUNCTION("""COMPUTED_VALUE"""),"1763") -> 1763 | F9: =IFERROR(__xludf.DUMMYFUNCTION("""COMPUTED_VALUE"""),"ismailm1989@gmail.com") -> ismailm1989@gmail.com | G9: =IFERROR(__xludf.DUMMYFUNCTION("""COMPUTED_VALUE"""),2.01129525491E11) -> 201129525491
A10: =IFERROR(__xludf.DUMMYFUNCTION("""COMPUTED_VALUE"""),"عمرو خطاب") -> عمرو خطاب | B10: =IFERROR(__xludf.DUMMYFUNCTION("""COMPUTED_VALUE"""),1.59150394389E11) -> 159150394389 | C10: =IFERROR(__xludf.DUMMYFUNCTION("""COMPUTED_VALUE"""),"عمرو خطاب") -> عمرو خطاب | D10: =IFERROR(__xludf.DUMMYFUNCTION("""COMPUTED_VALUE"""),"443") -> 443 | F10: =IFERROR(__xludf.DUMMYFUNCTION("""COMPUTED_VALUE"""),"amr.khattab@nagwa.com") -> amr.khattab@nagwa.com
A11: =IFERROR(__xludf.DUMMYFUNCTION("""COMPUTED_VALUE"""),"حسين مصطفى") -> حسين مصطفى | B11: =IFERROR(__xludf.DUMMYFUNCTION("""COMPUTED_VALUE"""),4.67134069813E11) -> 467134069813 | C11: =IFERROR(__xludf.DUMMYFUNCTION("""COMPUTED_VALUE"""),"حسين مصطفى") -> حسين مصطفى | D11: =IFERROR(__xludf.DUMMYFUNCTION("""COMPUTED_VALUE"""),"1127") -> 1127 | E11: =IFERROR(__xludf.DUMMYFUNCTION("""COMPUTED_VALUE"""),"EG04-EG05-EG06-EG07-EG08-EG09-EG10-EG11-EG12") -> EG04-EG05-EG06-EG07-EG08-EG09-EG10-EG11-EG12 | F11: =IFERROR(__xludf.DUMMYFUNCTION("""COMPUTED_VALUE"""),"hussein.mostafa@nagwa.com") -> hussein.mostafa@nagwa.com | G11: =IFERROR(__xludf.DUMMYFUNCTION("""COMPUTED_VALUE"""),2.01091050146E11) -> 201091050146
A12: =IFERROR(__xludf.DUMMYFUNCTION("""COMPUTED_VALUE"""),"علياء مكاوي") -> علياء مكاوي | B12: =IFERROR(__xludf.DUMMYFUNCTION("""COMPUTED_VALUE"""),6.15158327698E11) -> 615158327698 | C12: =IFERROR(__xludf.DUMMYFUNCTION("""COMPUTED_VALUE"""),"علياء مكاوي") -> علياء مكاوي | D12: =IFERROR(__xludf.DUMMYFUNCTION("""COMPUTED_VALUE"""),"1471") -> 1471 | E12: =IFERROR(__xludf.DUMMYFUNCTION("""COMPUTED_VALUE"""),"EG04-EG05-EG06-EG07-EG08-EG09") -> EG04-EG05-EG06-EG07-EG08-EG09 | F12: =IFERROR(__xludf.DUMMYFUNCTION("""COMPUTED_VALUE"""),"aliaa.makkawy@nagwa.com") -> aliaa.makkawy@nagwa.com | G12: =IFERROR(__xludf.DUMMYFUNCTION("""COMPUTED_VALUE"""),2.01063570903E11) -> 201063570903
A13: =IFERROR(__xludf.DUMMYFUNCTION("""COMPUTED_VALUE"""),"زينة الشيخ") -> زينة الشيخ | B13: =IFERROR(__xludf.DUMMYFUNCTION("""COMPUTED_VALUE"""),6.32164034291E11) -> 632164034291 | C13: =IFERROR(__xludf.DUMMYFUNCTION("""COMPUTED_VALUE"""),"زينة الشيخ") -> زينة الشيخ | D13: =IFERROR(__xludf.DUMMYFUNCTION("""COMPUTED_VALUE"""),"1004") -> 1004 | E13: =IFERROR(__xludf.DUMMYFUNCTION("""COMPUTED_VALUE"""),"EG04-EG05-EG06-EG07-EG08-EG09") -> EG04-EG05-EG06-EG07-EG08-EG09 | F13: =IFERROR(__xludf.DUMMYFUNCTION("""COMPUTED_VALUE"""),"zeina.elsheikh@nagwa.com") -> zeina.elsheikh@nagwa.com | G13: =IFERROR(__xludf.DUMMYFUNCTION("""COMPUTED_VALUE"""),"01097890222") -> 01097890222
A14: =IFERROR(__xludf.DUMMYFUNCTION("""COMPUTED_VALUE"""),"إسلام محمد") -> إسلام محمد | B14: =IFERROR(__xludf.DUMMYFUNCTION("""COMPUTED_VALUE"""),1.70181505929E11) -> 170181505929 | C14: =IFERROR(__xludf.DUMMYFUNCTION("""COMPUTED_VALUE"""),"إسلام محمد") -> إسلام محمد | D14: =IFERROR(__xludf.DUMMYFUNCTION("""COMPUTED_VALUE"""),"1647") -> 1647 | F14: =IFERROR(__xludf.DUMMYFUNCTION("""COMPUTED_VALUE"""),"eslam.mohamed@nagwa.com") -> eslam.mohamed@nagwa.com | G14: =IFERROR(__xludf.DUMMYFUNCTION("""COMPUTED_VALUE"""),"01097158020") -> 01097158020
A15: =IFERROR(__xludf.DUMMYFUNCTION("""COMPUTED_VALUE"""),"محمد رفعت") -> محمد رفعت | B15: =IFERROR(__xludf.DUMMYFUNCTION("""COMPUTED_VALUE"""),6.98108096794E11) -> 698108096794 | C15: =IFERROR(__xludf.DUMMYFUNCTION("""COMPUTED_VALUE"""),"محمد رفعت") -> محمد رفعت | D15: =IFERROR(__xludf.DUMMYFUNCTION("""COMPUTED_VALUE"""),"1776") -> 1776 | F15: =IFERROR(__xludf.DUMMYFUNCTION("""COMPUTED_VALUE"""),"seniormaths25@gmail.com") -> seniormaths25@gmail.com | G15: =IFERROR(__xludf.DUMMYFUNCTION("""COMPUTED_VALUE"""),"01129242524") -> 01129242524
A16: =IFERROR(__xludf.DUMMYFUNCTION("""COMPUTED_VALUE"""),"نورهان حشاد") -> نورهان حشاد | B16: =IFERROR(__xludf.DUMMYFUNCTION("""COMPUTED_VALUE"""),4.08124082075E11) -> 408124082075 | C16: =IFERROR(__xludf.DUMMYFUNCTION("""COMPUTED_VALUE"""),"نورهان حشاد") -> نورهان حشاد | D16: =IFERROR(__xludf.DUMMYFUNCTION("""COMPUTED_VALUE"""),1363.0) -> 1363 | F16: =IFERROR(__xludf.DUMMYFUNCTION("""COMPUTED_VALUE"""),"nourhan.hashad@nagwa.com") -> nourhan.hashad@nagwa.com | G16: =IFERROR(__xludf.DUMMYFUNCTION("""COMPUTED_VALUE"""),2.01112094005E11) -> 201112094005
A17: =IFERROR(__xludf.DUMMYFUNCTION("""COMPUTED_VALUE"""),"أحمد عماد") -> أحمد عماد | B17: =IFERROR(__xludf.DUMMYFUNCTION("""COMPUTED_VALUE"""),3.52134305787E11) -> 352134305787 | C17: =IFERROR(__xludf.DUMMYFUNCTION("""COMPUTED_VALUE"""),"أحمد عماد") -> أحمد عماد | D17: =IFERROR(__xludf.DUMMYFUNCTION("""COMPUTED_VALUE"""),"1212") -> 1212
A18: =IFERROR(__xludf.DUMMYFUNCTION("""COMPUTED_VALUE"""),"شادي خالد") -> شادي خالد | B18: =IFERROR(__xludf.DUMMYFUNCTION("""COMPUTED_VALUE"""),6.48193010591E11) -> 648193010591 | C18: =IFERROR(__xludf.DUMMYFUNCTION("""COMPUTED_VALUE"""),"شادي خالد") -> شادي خالد | D18: =IFERROR(__xludf.DUMMYFUNCTION("""COMPUTED_VALUE"""),"1087") -> 1087 | E18: =IFERROR(__xludf.DUMMYFUNCTION("""COMPUTED_VALUE"""),"EG10-EG11-G12") -> EG10-EG11-G12 | F18: =IFERROR(__xludf.DUMMYFUNCTION("""COMPUTED_VALUE"""),"shady.donia@nagwa.com") -> shady.donia@nagwa.com | G18: =IFERROR(__xludf.DUMMYFUNCTION("""COMPUTED_VALUE"""),2.01119117049E11) -> 201119117049
A19: =IFERROR(__xludf.DUMMYFUNCTION("""COMPUTED_VALUE"""),"ملك عليوي") -> ملك عليوي | B19: =IFERROR(__xludf.DUMMYFUNCTION("""COMPUTED_VALUE"""),5.35169041274E11) -> 535169041274 | C19: =IFERROR(__xludf.DUMMYFUNCTION("""COMPUTED_VALUE"""),"ملك عليوي") -> ملك عليوي | D19: =IFERROR(__xludf.DUMMYFUNCTION("""COMPUTED_VALUE"""),"1490") -> 1490 | E19: =IFERROR(__xludf.DUMMYFUNCTION("""COMPUTED_VALUE"""),"EG10-EG11") -> EG10-EG11 | F19: =IFERROR(__xludf.DUMMYFUNCTION("""COMPUTED_VALUE"""),"malak.maliwy@gmail.com") -> malak.maliwy@gmail.com
A20: =IFERROR(__xludf.DUMMYFUNCTION("""COMPUTED_VALUE"""),"عمرو خليل") -> عمرو خليل | B20: =IFERROR(__xludf.DUMMYFUNCTION("""COMPUTED_VALUE"""),8.95194823203E11) -> 895194823203 | C20: =IFERROR(__xludf.DUMMYFUNCTION("""COMPUTED_VALUE"""),"عمرو خليل") -> عمرو خليل | D20: =IFERROR(__xludf.DUMMYFUNCTION("""COMPUTED_VALUE"""),"1779") -> 1779 | F20: =IFERROR(__xludf.DUMMYFUNCTION("""COMPUTED_VALUE"""),"eng.amrkhalil2014@gmail.com") -> eng.amrkhalil2014@gmail.com | G20: =IFERROR(__xludf.DUMMYFUNCTION("""COMPUTED_VALUE"""),2.0114648675E11) -> 201146486750
A21: =IFERROR(__xludf.DUMMYFUNCTION("""COMPUTED_VALUE"""),"أحمد هنداوي") -> أحمد هنداوي | B21: =IFERROR(__xludf.DUMMYFUNCTION("""COMPUTED_VALUE"""),2.3819723036E11) -> 238197230360 | C21: =IFERROR(__xludf.DUMMYFUNCTION("""COMPUTED_VALUE"""),"أحمد هنداوي") -> أحمد هنداوي | D21: =IFERROR(__xludf.DUMMYFUNCTION("""COMPUTED_VALUE"""),"#N/A") -> #N/A | F21: =IFERROR(__xludf.DUMMYFUNCTION("""COMPUTED_VALUE"""),"ahmed.hindawi@nagwa.com") -> ahmed.hindawi@nagwa.com
A22: =IFERROR(__xludf.DUMMYFUNCTION("""COMPUTED_VALUE"""),"عصام عمر") -> عصام عمر | B22: =IFERROR(__xludf.DUMMYFUNCTION("""COMPUTED_VALUE"""),1.42159241646E11) -> 142159241646 | C22: =IFERROR(__xludf.DUMMYFUNCTION("""COMPUTED_VALUE"""),"عصام عمر") -> عصام عمر | D22: =IFERROR(__xludf.DUMMYFUNCTION("""COMPUTED_VALUE"""),"1534") -> 1534 | F22: =IFERROR(__xludf.DUMMYFUNCTION("""COMPUTED_VALUE"""),"essam.omar@nagwa.com") -> essam.omar@nagwa.com | G22: =IFERROR(__xludf.DUMMYFUNCTION("""COMPUTED_VALUE"""),2.01113618461E11) -> 201113618461
A23: =IFERROR(__xludf.DUMMYFUNCTION("""COMPUTED_VALUE"""),"محمد رمضان") -> محمد رمضان | B23: =IFERROR(__xludf.DUMMYFUNCTION("""COMPUTED_VALUE"""),9.4018209041E11) -> 940182090410 | C23: =IFERROR(__xludf.DUMMYFUNCTION("""COMPUTED_VALUE"""),"محمد رمضان") -> محمد رمضان | D23: =IFERROR(__xludf.DUMMYFUNCTION("""COMPUTED_VALUE"""),"575") -> 575 | F23: =IFERROR(__xludf.DUMMYFUNCTION("""COMPUTED_VALUE"""),"mohammed.elsayed.ramadan@nagwa.com") -> mohammed.elsayed.ramadan@nagwa.com | G23: =IFERROR(__xludf.DUMMYFUNCTION("""COMPUTED_VALUE"""),2.01025475475E11) -> 201025475475
A24: =IFERROR(__xludf.DUMMYFUNCTION("""COMPUTED_VALUE"""),"محمد إمام") -> محمد إمام | B24: =IFERROR(__xludf.DUMMYFUNCTION("""COMPUTED_VALUE"""),9.13169734907E11) -> 913169734907 | C24: =IFERROR(__xludf.DUMMYFUNCTION("""COMPUTED_VALUE"""),"محمد إمام") -> محمد إمام | D24: =IFERROR(__xludf.DUMMYFUNCTION("""COMPUTED_VALUE"""),"1759") -> 1759 | E24: =IFERROR(__xludf.DUMMYFUNCTION("""COMPUTED_VALUE"""),"EG10-EG11-G12") -> EG10-EG11-G12
A25: =IFERROR(__xludf.DUMMYFUNCTION("""COMPUTED_VALUE"""),"أحمد ياقوت") -> أحمد ياقوت | B25: =IFERROR(__xludf.DUMMYFUNCTION("""COMPUTED_VALUE"""),2.84105320408E11) -> 284105320408 | C25: =IFERROR(__xludf.DUMMYFUNCTION("""COMPUTED_VALUE"""),"أحمد ياقوت") -> أحمد ياقوت | D25: =IFERROR(__xludf.DUMMYFUNCTION("""COMPUTED_VALUE"""),"1757") -> 1757 | E25: =IFERROR(__xludf.DUMMYFUNCTION("""COMPUTED_VALUE"""),"لم يقبل نظام المحاسبة الجديد والتسجيلات فقرر الاستقالة، فيرجى التواصل معه وتنفيذ إجراءات إنهاء التعاقد وتسليم العهدة") -> لم يقبل نظام المحاسبة الجديد والتسجيلات فقرر الاستقالة، فيرجى التواصل معه وتنفيذ إجراءات إنهاء التعاقد وتسليم العهدة
A26: =IFERROR(__xludf.DUMMYFUNCTION("""COMPUTED_VALUE"""),"مريم حسين") -> مريم حسين | B26: =IFERROR(__xludf.DUMMYFUNCTION("""COMPUTED_VALUE"""),6.95180376491E11) -> 695180376491 | C26: =IFERROR(__xludf.DUMMYFUNCTION("""COMPUTED_VALUE"""),"مريم حسين") -> مريم حسين | D26: =IFERROR(__xludf.DUMMYFUNCTION("""COMPUTED_VALUE"""),"1758") -> 1758 | F26: =IFERROR(__xludf.DUMMYFUNCTION("""COMPUTED_VALUE"""),"mero.mro9@gmail.com") -> mero.mro9@gmail.com
A27: =IFERROR(__xludf.DUMMYFUNCTION("""COMPUTED_VALUE"""),"محمد منصور") -> محمد منصور | B27: =IFERROR(__xludf.DUMMYFUNCTION("""COMPUTED_VALUE"""),5.60135012165E11) -> 560135012165 | C27: =IFERROR(__xludf.DUMMYFUNCTION("""COMPUTED_VALUE"""),"محمد منصور") -> محمد منصور | D27: =IFERROR(__xludf.DUMMYFUNCTION("""COMPUTED_VALUE"""),"1760") -> 1760 | E27: =IFERROR(__xludf.DUMMYFUNCTION("""COMPUTED_VALUE"""),"EG10-EG11-G12") -> EG10-EG11-G12 | F27: =IFERROR(__xludf.DUMMYFUNCTION("""COMPUTED_VALUE"""),"mansourphy@gmail.com") -> mansourphy@gmail.com | G27: =IFERROR(__xludf.DUMMYFUNCTION("""COMPUTED_VALUE"""),2.01069555347E11) -> 201069555347
A28: =IFERROR(__xludf.DUMMYFUNCTION("""COMPUTED_VALUE"""),"محمود أبو المجد") -> محمود أبو المجد | B28: =IFERROR(__xludf.DUMMYFUNCTION("""COMPUTED_VALUE"""),2.7917049757E11) -> 279170497570 | C28: =IFERROR(__xludf.DUMMYFUNCTION("""COMPUTED_VALUE"""),"محمود أبو المجد") -> محمود أبو المجد | D28: =IFERROR(__xludf.DUMMYFUNCTION("""COMPUTED_VALUE"""),"1243") -> 1243 | E28: =IFERROR(__xludf.DUMMYFUNCTION("""COMPUTED_VALUE"""),"EG04-EG05-EG06-G7-جيولوجيا EG12") -> EG04-EG05-EG06-G7-جيولوجيا EG12 | F28: =IFERROR(__xludf.DUMMYFUNCTION("""COMPUTED_VALUE"""),"mahmoud.aboelmagd@nagwa.com") -> mahmoud.aboelmagd@nagwa.com
A29: =IFERROR(__xludf.DUMMYFUNCTION("""COMPUTED_VALUE"""),"أحمد عبد اللطيف") -> أحمد عبد اللطيف | B29: =IFERROR(__xludf.DUMMYFUNCTION("""COMPUTED_VALUE"""),6.24104658072E11) -> 624104658072 | C29: =IFERROR(__xludf.DUMMYFUNCTION("""COMPUTED_VALUE"""),"أحمد عبد اللطيف") -> أحمد عبد اللطيف | D29: =IFERROR(__xludf.DUMMYFUNCTION("""COMPUTED_VALUE"""),"1265") -> 1265 | F29: =IFERROR(__xludf.DUMMYFUNCTION("""COMPUTED_VALUE"""),"ahmed.abdellatif@nagwa.com") -> ahmed.abdellatif@nagwa.com | G29: =IFERROR(__xludf.DUMMYFUNCTION("""COMPUTED_VALUE"""),2.01018842229E11) -> 201018842229
A30: =IFERROR(__xludf.DUMMYFUNCTION("""COMPUTED_VALUE"""),"رامي فاروق") -> رامي فاروق | B30: =IFERROR(__xludf.DUMMYFUNCTION("""COMPUTED_VALUE"""),6.80190738426E11) -> 680190738426 | C30: =IFERROR(__xludf.DUMMYFUNCTION("""COMPUTED_VALUE"""),"رامي فاروق") -> رامي فاروق | D30: =IFERROR(__xludf.DUMMYFUNCTION("""COMPUTED_VALUE"""),"1766") -> 1766 | F30: =IFERROR(__xludf.DUMMYFUNCTION("""COMPUTED_VALUE"""),"ramyfarouk9333@gmail.com") -> ramyfarouk9333@gmail.com | G30: =IFERROR(__xludf.DUMMYFUNCTION("""COMPUTED_VALUE"""),"01224288238") -> 01224288238
A31: =IFERROR(__xludf.DUMMYFUNCTION("""COMPUTED_VALUE"""),"سما الإبراشي") -> سما الإبراشي | B31: =IFERROR(__xludf.DUMMYFUNCTION("""COMPUTED_VALUE"""),1.56154179702E11) -> 156154179702 | C31: =IFERROR(__xludf.DUMMYFUNCTION("""COMPUTED_VALUE"""),"سما الإبراشي") -> سما الإبراشي | D31: =IFERROR(__xludf.DUMMYFUNCTION("""COMPUTED_VALUE"""),"1777") -> 1777 | E31: =IFERROR(__xludf.DUMMYFUNCTION("""COMPUTED_VALUE"""),"EG10-EG11-G12") -> EG10-EG11-G12 | F31: =IFERROR(__xludf.DUMMYFUNCTION("""COMPUTED_VALUE"""),"sama.elberashy@gmail.com") -> sama.elberashy@gmail.com | G31: =IFERROR(__xludf.DUMMYFUNCTION("""COMPUTED_VALUE"""),2.01001344221E11) -> 201001344221
A32: =IFERROR(__xludf.DUMMYFUNCTION("""COMPUTED_VALUE"""),"مينا جاد") -> مينا جاد | B32: =IFERROR(__xludf.DUMMYFUNCTION("""COMPUTED_VALUE"""),8.46101762818E11) -> 846101762818 | C32: =IFERROR(__xludf.DUMMYFUNCTION("""COMPUTED_VALUE"""),"مينا جاد") -> مينا جاد | D32: =IFERROR(__xludf.DUMMYFUNCTION("""COMPUTED_VALUE"""),1781.0) -> 1781
A33: =IFERROR(__xludf.DUMMYFUNCTION("""COMPUTED_VALUE"""),"أحمد حسن") -> أحمد حسن | B33: =IFERROR(__xludf.DUMMYFUNCTION("""COMPUTED_VALUE"""),4.80103238452E11) -> 480103238452 | C33: =IFERROR(__xludf.DUMMYFUNCTION("""COMPUTED_VALUE"""),"أحمد حسن") -> أحمد حسن | D33: =IFERROR(__xludf.DUMMYFUNCTION("""COMPUTED_VALUE"""),"1762") -> 1762 | F33: =IFERROR(__xludf.DUMMYFUNCTION("""COMPUTED_VALUE"""),"ahmedhassan99967@gmail.com") -> ahmedhassan99967@gmail.com | G33: =IFERROR(__xludf.DUMMYFUNCTION("""COMPUTED_VALUE"""),2.01007787118E11) -> 201007787118
A34: =IFERROR(__xludf.DUMMYFUNCTION("""COMPUTED_VALUE"""),"جهاد بدر") -> جهاد بدر | B34: =IFERROR(__xludf.DUMMYFUNCTION("""COMPUTED_VALUE"""),5.24151240185E11) -> 524151240185 | C34: =IFERROR(__xludf.DUMMYFUNCTION("""COMPUTED_VALUE"""),"جهاد بدر") -> جهاد بدر | D34: =IFERROR(__xludf.DUMMYFUNCTION("""COMPUTED_VALUE"""),"1786") -> 1786 | F34: =IFERROR(__xludf.DUMMYFUNCTION("""COMPUTED_VALUE"""),"gehadbadr89@gmail.com") -> gehadbadr89@gmail.com | G34: =IFERROR(__xludf.DUMMYFUNCTION("""COMPUTED_VALUE"""),"01090297182") -> 01090297182
A35: =IFERROR(__xludf.DUMMYFUNCTION("""COMPUTED_VALUE"""),"طارق سليم") -> طارق سليم | B35: =IFERROR(__xludf.DUMMYFUNCTION("""COMPUTED_VALUE"""),3.79176206354E11) -> 379176206354 | C35: =IFERROR(__xludf.DUMMYFUNCTION("""COMPUTED_VALUE"""),"طارق سليم") -> طارق سليم | D35: =IFERROR(__xludf.DUMMYFUNCTION("""COMPUTED_VALUE"""),"1778") -> 1778 | F35: =IFERROR(__xludf.DUMMYFUNCTION("""COMPUTED_VALUE"""),"tareksleem606@gmail.com") -> tareksleem606@gmail.com | G35: =IFERROR(__xludf.DUMMYFUNCTION("""COMPUTED_VALUE"""),2.01001599199E11) -> 201001599199
A36: =IFERROR(__xludf.DUMMYFUNCTION("""COMPUTED_VALUE"""),"أحمد علاء") -> أحمد علاء | B36: =IFERROR(__xludf.DUMMYFUNCTION("""COMPUTED_VALUE"""),3.52179823813E11) -> 352179823813 | C36: =IFERROR(__xludf.DUMMYFUNCTION("""COMPUTED_VALUE"""),"أحمد علاء") -> أحمد علاء | D36: =IFERROR(__xludf.DUMMYFUNCTION("""COMPUTED_VALUE"""),"1765") -> 1765 | F36: =IFERROR(__xludf.DUMMYFUNCTION("""COMPUTED_VALUE"""),"aassllyyaa68@gmail.com") -> aassllyyaa68@gmail.com
A37: =IFERROR(__xludf.DUMMYFUNCTION("""COMPUTED_VALUE"""),"أحمد عاطف") -> أحمد عاطف | B37: =IFERROR(__xludf.DUMMYFUNCTION("""COMPUTED_VALUE"""),3.08137598241E11) -> 308137598241 | C37: =IFERROR(__xludf.DUMMYFUNCTION("""COMPUTED_VALUE"""),"أحمد عاطف") -> أحمد عاطف | D37: =IFERROR(__xludf.DUMMYFUNCTION("""COMPUTED_VALUE"""),"1775") -> 1775 | F37: =IFERROR(__xludf.DUMMYFUNCTION("""COMPUTED_VALUE"""),"ahmedatef386@gmail.com") -> ahmedatef386@gmail.com | G37: =IFERROR(__xludf.DUMMYFUNCTION("""COMPUTED_VALUE"""),2.01098614126E11) -> 201098614126
A38: =IFERROR(__xludf.DUMMYFUNCTION("""COMPUTED_VALUE"""),"محمد عصام") -> محمد عصام | B38: =IFERROR(__xludf.DUMMYFUNCTION("""COMPUTED_VALUE"""),5.92179807615E11) -> 592179807615 | C38: =IFERROR(__xludf.DUMMYFUNCTION("""COMPUTED_VALUE"""),"محمد عصام") -> محمد عصام | D38: =IFERROR(__xludf.DUMMYFUNCTION("""COMPUTED_VALUE"""),"1277") -> 1277 | E38: =IFERROR(__xludf.DUMMYFUNCTION("""COMPUTED_VALUE"""),"EG07-EG08-EG09") -> EG07-EG08-EG09 | F38: =IFERROR(__xludf.DUMMYFUNCTION("""COMPUTED_VALUE"""),"modares2525@gmail.com") -> modares2525@gmail.com | G38: =IFERROR(__xludf.DUMMYFUNCTION("""COMPUTED_VALUE"""),2.01116153885E11) -> 201116153885
A39: =IFERROR(__xludf.DUMMYFUNCTION("""COMPUTED_VALUE"""),"وائل سلطان") -> وائل سلطان | B39: =IFERROR(__xludf.DUMMYFUNCTION("""COMPUTED_VALUE"""),4.15194597216E11) -> 415194597216 | C39: =IFERROR(__xludf.DUMMYFUNCTION("""COMPUTED_VALUE"""),"وائل سلطان") -> وائل سلطان | D39: =IFERROR(__xludf.DUMMYFUNCTION("""COMPUTED_VALUE"""),"1787") -> 1787 | F39: =IFERROR(__xludf.DUMMYFUNCTION("""COMPUTED_VALUE"""),"abomahmoudsoultan@gmail.com") -> abomahmoudsoultan@gmail.com | G39: =IFERROR(__xludf.DUMMYFUNCTION("""COMPUTED_VALUE"""),"00201153335900") -> 00201153335900
A40: =IFERROR(__xludf.DUMMYFUNCTION("""COMPUTED_VALUE"""),"أندرو ثروت") -> أندرو ثروت | B40: =IFERROR(__xludf.DUMMYFUNCTION("""COMPUTED_VALUE"""),4.17127195646E11) -> 417127195646 | C40: =IFERROR(__xludf.DUMMYFUNCTION("""COMPUTED_VALUE"""),"أندرو ثروت") -> أندرو ثروت | D40: =IFERROR(__xludf.DUMMYFUNCTION("""COMPUTED_VALUE"""),"1788") -> 1788 | E40: =IFERROR(__xludf.DUMMYFUNCTION("""COMPUTED_VALUE"""),"EG07-EG08-EG09") -> EG07-EG08-EG09 | F40: =IFERROR(__xludf.DUMMYFUNCTION("""COMPUTED_VALUE"""),"andrewtharwatfikry@gmail.com") -> andrewtharwatfikry@gmail.com | G40: =IFERROR(__xludf.DUMMYFUNCTION("""COMPUTED_VALUE"""),"01205947696") -> 01205947696
...
