Workbook

Sheet Sheet1
A1: Tutor Name | B1: Tutor ID | C1: Stage | D1: Subject | E1: Status | F1: HR ID | G1: Stage Range | H1: Email | I1: Mobile Number
A2: إيمان محمود | B2: 137198142829 | C2: Lower Primary | D2: Discover | E2: Backup | F2: =VLOOKUP(A2,Sheet2!C:D,2,0) -> 1840 | G2: =VLOOKUP(A2,Sheet2!C:E,3,0) -> EG04-EG05-EG06 | H2: =VLOOKUP(A2,Sheet2!A:F,6,0) -> imaneabada@gmail.com | I2: =VLOOKUP(A2,Sheet2!C:G,5,0) -> 01005729272
A3: نسرين زهران | B3: 193156013197 | C3: Lower Primary | D3: Discover | E3: Active | F3: =VLOOKUP(A3,Sheet2!C:D,2,0) -> 2172 | G3: =VLOOKUP(A3,Sheet2!C:E,3,0) -> EG01-EG02-EG03 | H3: =VLOOKUP(A3,Sheet2!A:F,6,0) -> the.peace20006@gmail.com | I3: =VLOOKUP(A3,Sheet2!C:G,5,0) -> 01067579926
A4: رحاب حمدي | B4: 838198456425 | C4: Lower Primary | D4: Discover | E4: Active | F4: =VLOOKUP(A4,Sheet2!C:D,2,0) -> 2171 | G4: =VLOOKUP(A4,Sheet2!C:E,3,0) -> EG01-EG02-EG03 | H4: =VLOOKUP(A4,Sheet2!A:F,6,0) -> rehab533@gmail.com | I4: =VLOOKUP(A4,Sheet2!C:G,5,0) -> 01019577994
A5: نرمين جلال | B5: 209148542918 | C5: Lower Primary | D5: Discover | E5: Active | F5: =VLOOKUP(A5,Sheet2!C:D,2,0) -> 2191 | G5: =VLOOKUP(A5,Sheet2!C:E,3,0) -> EG01-EG02-EG03-EG04-EG05 | H5: =VLOOKUP(A5,Sheet2!A:F,6,0) -> norenosman11@yahoo.com | I5: =VLOOKUP(A5,Sheet2!C:G,5,0) -> 01285292060
A6: ندى عبد النبي | B6: 105150134960 | C6: Lower Primary | D6: Discover | E6: Active | F6: =VLOOKUP(A6,Sheet2!C:D,2,0) -> 2212 | G6: =VLOOKUP(A6,Sheet2!C:E,3,0) -> EG01-EG02-EG03 | H6: =VLOOKUP(A6,Sheet2!A:F,6,0) -> nadalisaid46@gmail.com | I6: =VLOOKUP(A6,Sheet2!C:G,5,0) -> 01273190435
A7: مروة مجدي | B7: 189108478931 | C7: Lower Primary | D7: Discover | E7: Active | F7: =VLOOKUP(A7,Sheet2!C:D,2,0) -> 2443 | G7: =VLOOKUP(A7,Sheet2!C:E,3,0) -> EG01-EG02-EG03 | H7: =VLOOKUP(A7,Sheet2!A:F,6,0) -> jodyy2007@gmail.com | I7: =VLOOKUP(A7,Sheet2!C:G,5,0) -> 01091927577
A8: يارا سلطان | B8: 919170561064 | C8: Lower Primary | D8: Discover | E8: Active | F8: =VLOOKUP(A8,Sheet2!C:D,2,0) -> 2561 | G8: =VLOOKUP(A8,Sheet2!C:E,3,0) -> EG01-EG02-EG03 | H8: =VLOOKUP(A8,Sheet2!A:F,6,0) -> ywael044@gmail.com | I8: =VLOOKUP(A8,Sheet2!C:G,5,0) -> 01271833101
A9: أسماء الحسيني | B9: 623157516497 | C9: Lower Primary | D9: Discover | E9: Active | F9: =VLOOKUP(A9,Sheet2!C:D,2,0) -> 2580 | G9: =VLOOKUP(A9,Sheet2!C:E,3,0) -> EG01-EG02-EG03 | H9: =VLOOKUP(A9,Sheet2!A:F,6,0) -> elhosseinyasmaa@gmail.com | I9: =VLOOKUP(A9,Sheet2!C:G,5,0) -> 01006995563
A10: دعاء مصطفى | B10: 634163474745 | C10: Lower Primary | D10: Discover | E10: Active | F10: =VLOOKUP(A10,Sheet2!C:D,2,0) -> 2722 | G10: =VLOOKUP(A10,Sheet2!C:E,3,0) -> EG01-EG02-EG03-EG04-EG05-EG06 | H10: =VLOOKUP(A10,Sheet2!A:F,6,0) -> doaamostafaalis@gmail.com | I10: =VLOOKUP(A10,Sheet2!C:G,5,0) -> 01012291825
A11: مونيكا إدوارد | B11: 194190610534 | C11: Lower Primary | D11: Discover | E11: Backup | F11: =VLOOKUP(A11,Sheet2!C:D,2,0) -> 2757 | G11: =VLOOKUP(A11,Sheet2!C:E,3,0) -> EG01-EG02-EG03-EG04 | H11: =VLOOKUP(A11,Sheet2!A:F,6,0) -> moneyedward37@gmail.com | I11: =VLOOKUP(A11,Sheet2!C:G,5,0) -> 01277626560
A12: دنيا فاروق | B12: 148126371346 | C12: Lower Primary | D12: Discover | E12: Backup | F12: =VLOOKUP(A12,Sheet2!C:D,2,0) -> 2745 | G12: =VLOOKUP(A12,Sheet2!C:E,3,0) -> EG01-EG02-EG03 | H12: =VLOOKUP(A12,Sheet2!A:F,6,0) -> doniafarouk2811@gmail.com | I12: =VLOOKUP(A12,Sheet2!C:G,5,0) -> 01201302647
A13: إيريني عاطف | B13: 530189784630 | C13: Lower Primary | D13: English | E13: Active | F13: =VLOOKUP(A13,Sheet2!C:D,2,0) -> 2003 | G13: =VLOOKUP(A13,Sheet2!C:E,3,0) -> EG01-EG02-EG03-EG04-EG05 | H13: =VLOOKUP(A13,Sheet2!A:F,6,0) -> erineyatef@gmail.com | I13: =VLOOKUP(A13,Sheet2!C:G,5,0) -> 01211816220
... A554: محمد سالم | B554: 709139503259 | C554: Secondary | D554: الفيزياء | E554: Backup | F554: =VLOOKUP(A554,Sheet2!C:D,2,0) -> 2096 | G554: =VLOOKUP(A554,Sheet2!C:E,3,0) -> EG10-EG11-G12 | H554: =VLOOKUP(A554,Sheet2!A:F,6,0) -> korashy.1411@gmail.com | I554: =VLOOKUP(A554,Sheet2!C:G,5,0) -> 01126633295
A555: محمد عماد عبد النبي الشحات | B555: =VLOOKUP(A555,Sheet2!A:B,2,0) -> #N/A | C555: Secondary | D555: علم النفس والاجتماع | E555: Resigned | F555: =VLOOKUP(A555,Sheet2!C:D,2,0) -> #N/A | G555: =VLOOKUP(A555,Sheet2!C:E,3,0) -> #N/A | H555: =VLOOKUP(A555,Sheet2!A:F,6,0) -> #N/A | I555: =VLOOKUP(A555,Sheet2!C:G,5,0) -> #N/A
A556: دسوقي إبراهيم | B556: 893140536419 | C556: Secondary | D556: علم النفس والاجتماع | E556: Backup | F556: =VLOOKUP(A556,Sheet2!C:D,2,0) -> 2199 | G556: =VLOOKUP(A556,Sheet2!C:E,3,0) -> EG10-EG11-G12 | H556: =VLOOKUP(A556,Sheet2!A:F,6,0) -> ebrahim2721976@gmail.com | I556: =VLOOKUP(A556,Sheet2!C:G,5,0) -> 0
A557: رشا نصير | B557: 942138286345 | C557: Secondary | D557: الكيمياء | E557: Inactive | F557: =VLOOKUP(A557,Sheet2!C:D,2,0) -> 1975 | G557: =VLOOKUP(A557,Sheet2!C:E,3,0) -> EG10-EG11-G12 | H557: =VLOOKUP(A557,Sheet2!A:F,6,0) -> rnosier.72@gmail.com | I557: =VLOOKUP(A557,Sheet2!C:G,5,0) -> 01004540715
A558: مازن جاد | B558: 452123973904 | C558: Secondary | D558: Chemistry | E558: Inactive | F558: =VLOOKUP(A558,Sheet2!C:D,2,0) -> 1330 | G558: =VLOOKUP(A558,Sheet2!C:E,3,0) -> 0 | H558: =VLOOKUP(A558,Sheet2!A:F,6,0) -> s-mazenhafez@zewailcity.edu.eg | I558: =VLOOKUP(A558,Sheet2!C:G,5,0) -> 0
A559: زكي سعيد | B559: 424154524098 | C559: Secondary | D559: English | E559: Inactive | F559: =VLOOKUP(A559,Sheet2!C:D,2,0) -> 2135 | G559: =VLOOKUP(A559,Sheet2!C:E,3,0) -> 0 | H559: =VLOOKUP(A559,Sheet2!A:F,6,0) -> zakisaeedfrs@gmail.com | I559: =VLOOKUP(A559,Sheet2!C:G,5,0) -> 01202812574
A560: أحمد يحيى | B560: 636182508414 | C560: Preparatory | D560: الرياضيات | E560: Resigned | F560: =VLOOKUP(A560,Sheet2!C:D,2,0) -> 1846 | G560: =VLOOKUP(A560,Sheet2!C:E,3,0) -> 0 | H560: =VLOOKUP(A560,Sheet2!A:F,6,0) -> 0 | I560: =VLOOKUP(A560,Sheet2!C:G,5,0) -> 0
A561: أماني نيكولا | B561: 626126867906 | C561: Preparatory | D561: English | E561: Inactive | F561: =VLOOKUP(A561,Sheet2!C:D,2,0) -> 1993 | G561: =VLOOKUP(A561,Sheet2!C:E,3,0) -> 0 | H561: =VLOOKUP(A561,Sheet2!A:F,6,0) -> amany.nicola6@gmail.com | I561: =VLOOKUP(A561,Sheet2!C:G,5,0) -> 01222711176
A562: فادي جبرائيل | B562: 675168783816 | C562: Secondary | D562: Chemistry | E562: Inactive | F562: =VLOOKUP(A562,Sheet2!C:D,2,0) -> 1909 | G562: =VLOOKUP(A562,Sheet2!C:E,3,0) -> EG10-EG11-G12 | H562: =VLOOKUP(A562,Sheet2!A:F,6,0) -> fady.gobrail@gmail.com | I562: =VLOOKUP(A562,Sheet2!C:G,5,0) -> 035400651
A563: رضا جبريل | B563: 198159430149 | C563: Secondary | D563: اللغة العربية | E563: Inactive | F563: =VLOOKUP(A563,Sheet2!C:D,2,0) -> 1083 | G563: =VLOOKUP(A563,Sheet2!C:E,3,0) -> EG10-EG11-EG12 | H563: =VLOOKUP(A563,Sheet2!A:F,6,0) -> 0 | I563: =VLOOKUP(A563,Sheet2!C:G,5,0) -> 0
A564: مروة مصطفى | B564: 963158235375 | C564: Secondary | D564: Español | E564: Inactive | F564: =VLOOKUP(A564,Sheet2!C:D,2,0) -> 2062 | G564: =VLOOKUP(A564,Sheet2!C:E,3,0) -> 0 | H564: =VLOOKUP(A564,Sheet2!A:F,6,0) -> marwa_mostafa_@hotmail.com | I564: =VLOOKUP(A564,Sheet2!C:G,5,0) -> 01003732776
A565: رضوى صبري | B565: 194141237816 | C565: Secondary | D565: Deutsch | E565: Inactive | F565: =VLOOKUP(A565,Sheet2!C:D,2,0) -> 1841 | G565: =VLOOKUP(A565,Sheet2!C:E,3,0) -> She won't be with us in the 2nd term. | H565: =VLOOKUP(A565,Sheet2!A:F,6,0) -> 0 | I565: =VLOOKUP(A565,Sheet2!C:G,5,0) -> 0
A566: بيشوي عادل | B566: 194194607634 | C566: Secondary | D566: Italiano | E566: Backup | F566: =VLOOKUP(A566,Sheet2!C:D,2,0) -> 2006 | G566: =VLOOKUP(A566,Sheet2!C:E,3,0) -> 0 | H566: =VLOOKUP(A566,Sheet2!A:F,6,0) -> bichoiadel@gmail.com | I566: =VLOOKUP(A566,Sheet2!C:G,5,0) -> 01283973691
A567: ماجدة محمد | B567: 973132386263 | C567: Secondary | D567: Español | E567: Backup | F567: =VLOOKUP(A567,Sheet2!C:D,2,0) -> 1798 | G567: =VLOOKUP(A567,Sheet2!C:E,3,0) -> 0 | H567: =VLOOKUP(A567,Sheet2!A:F,6,0) -> magdaharidy96@gmail.com | I567: =VLOOKUP(A567,Sheet2!C:G,5,0) -> 01011902047
... A625: مارسيل سميح | B625: 945182868176 | C625: Higher Primary | D625: Mathematics | E625: Resigned | F625: =VLOOKUP(A625,Sheet2!C:D,2,0) -> 2074 | G625: =VLOOKUP(A625,Sheet2!C:E,3,0) -> 0 | H625: =VLOOKUP(A625,Sheet2!A:F,6,0) -> 0 | I625: =VLOOKUP(A625,Sheet2!C:G,5,0) -> 0
A626: عبده شيتاوي | B626: =VLOOKUP(A626,Sheet2!A:B,2,0) -> #N/A | C626: Secondary | D626: الفيزياء | E626: New Hire | F626: =VLOOKUP(A626,Sheet2!C:D,2,0) -> #N/A | G626: =VLOOKUP(A626,Sheet2!C:E,3,0) -> #N/A | H626: =VLOOKUP(A626,Sheet2!A:F,6,0) -> #N/A | I626: =VLOOKUP(A626,Sheet2!C:G,5,0) -> #N/A
A627: محمد رجب | B627: 137159402437 | C627: Secondary | D627: الفيزياء | E627: Resigned | F627: =VLOOKUP(A627,Sheet2!C:D,2,0) -> 2336 | G627: =VLOOKUP(A627,Sheet2!C:E,3,0) -> G11-G12 | H627: =VLOOKUP(A627,Sheet2!A:F,6,0) -> mohamedr7713253@gmail.com | I627: =VLOOKUP(A627,Sheet2!C:G,5,0) -> 01007713253
A628: ميرنا طارق | B628: 454134237907 | C628: Secondary | D628: Français | E628: Backup | F628: =VLOOKUP(A628,Sheet2!C:D,2,0) -> 2341 | G628: =VLOOKUP(A628,Sheet2!C:E,3,0) -> 0 | H628: =VLOOKUP(A628,Sheet2!A:F,6,0) -> mirna_tareksalah97@yahoo.com | I628: =VLOOKUP(A628,Sheet2!C:G,5,0) -> 01225300158
A629: منى أخنوخ | B629: 937186279710 | C629: Secondary | D629: Français | E629: Backup | F629: =VLOOKUP(A629,Sheet2!C:D,2,0) -> 2338 | G629: =VLOOKUP(A629,Sheet2!C:E,3,0) -> 0 | H629: =VLOOKUP(A629,Sheet2!A:F,6,0) -> remonamoon@gmail.com | I629: =VLOOKUP(A629,Sheet2!C:G,5,0) -> 01003647713
A630: إسلام درويش | B630: 857181851641 | C630: Secondary | D630: اللغة العربية | E630: Resigned | F630: =VLOOKUP(A630,Sheet2!C:D,2,0) -> 2263 | G630: =VLOOKUP(A630,Sheet2!C:E,3,0) -> EG08-EG09-EG10-EG11-EG12 | H630: =VLOOKUP(A630,Sheet2!A:F,6,0) -> islam.m.darweesh@gmail.com | I630: =VLOOKUP(A630,Sheet2!C:G,5,0) -> 01153839716
A631: سارة إبراهيم سامي | B631: =VLOOKUP(A631,Sheet2!A:B,2,0) -> No ID | C631: Lower Primary | D631: English | E631: Resigned | F631: =VLOOKUP(A631,Sheet2!C:D,2,0) -> 0 | G631: =VLOOKUP(A631,Sheet2!C:E,3,0) -> 0 | H631: =VLOOKUP(A631,Sheet2!A:F,6,0) -> 0 | I631: =VLOOKUP(A631,Sheet2!C:G,5,0) -> 0
A632: نرمين سعيد | B632: 716141713108 | C632: Preparatory | D632: Science | E632: Inactive | F632: =VLOOKUP(A632,Sheet2!C:D,2,0) -> 2355 | G632: =VLOOKUP(A632,Sheet2!C:E,3,0) -> EG07-EG08-EG09 | H632: =VLOOKUP(A632,Sheet2!A:F,6,0) -> nrmeensaeed28191@gmail.com | I632: =VLOOKUP(A632,Sheet2!C:G,5,0) -> 01065167912
A633: عبد الرحمن رمضان | B633: 905158654524 | C633: Higher Primary | D633: الدراسات الاجتماعية | E633: New Hire | F633: =VLOOKUP(A633,Sheet2!C:D,2,0) -> 0 | G633: =VLOOKUP(A633,Sheet2!C:E,3,0) -> 0 | H633: =VLOOKUP(A633,Sheet2!A:F,6,0) -> rabdo6492@gmail.com | I633: =VLOOKUP(A633,Sheet2!C:G,5,0) -> 0
A634: نهال زاهر | B634: 783123583101 | C634: Secondary | D634: English | E634: Inactive | F634: =VLOOKUP(A634,Sheet2!C:D,2,0) -> 2376 | G634: =VLOOKUP(A634,Sheet2!C:E,3,0) -> EG09-EG10-EG11 | H634: =VLOOKUP(A634,Sheet2!A:F,6,0) -> nehalzaher@gmail.com | I634: =VLOOKUP(A634,Sheet2!C:G,5,0) -> 91111734555
A635: ريهام سلطان | B635: 529183826745 | C635: Secondary | D635: Français | E635: Backup | F635: =VLOOKUP(A635,Sheet2!C:D,2,0) -> 2379 | G635: =VLOOKUP(A635,Sheet2!C:E,3,0) -> 0 | H635: =VLOOKUP(A635,Sheet2!A:F,6,0) -> rehamsultan718@gmail.com | I635: =VLOOKUP(A635,Sheet2!C:G,5,0) -> 01099408611
A636: إيمان السيد | B636: 794175742320 | C636: Higher Primary | D636: اللغة العربية | E636: Resigned | F636: =VLOOKUP(A636,Sheet2!C:D,2,0) -> 2370 | G636: =VLOOKUP(A636,Sheet2!C:E,3,0) -> لم يعجبها نظام الدفع والتسجيلات وقالت إنها لا تريد أن تقدم وقتها في "حاجة غير مجدية" واستقالت بالفعل | H636: =VLOOKUP(A636,Sheet2!A:F,6,0) -> 0 | I636: =VLOOKUP(A636,Sheet2!C:G,5,0) -> 0
A637: أحمد صالح | B637: 587173545189 | C637: Secondary | D637: اللغة العربية | E637: Inactive | F637: =VLOOKUP(A637,Sheet2!C:D,2,0) -> 2371 | G637: =VLOOKUP(A637,Sheet2!C:E,3,0) -> EG08-EG09-EG10-EG11-EG12 | H637: =VLOOKUP(A637,Sheet2!A:F,6,0) -> saleh8015@gmail.com | I637: =VLOOKUP(A637,Sheet2!C:G,5,0) -> 01122606455
...

Sheet Data
A1: Tutor Name | B1: Tutor ID | C1: Stage | D1: Subject | E1: Status | F1: HR ID | G1: Stage Range | H1: email | I1: Mobile Number
A2: إيمان محمود | B2: 137198142829 | C2: Lower Primary | D2: Discover | E2: Backup | F2: 1840 | G2: EG04-EG05-EG06 | H2: imaneabada@gmail.com | I2: 01005729272
A3: نسرين زهران | B3: 193156013197 | C3: Lower Primary | D3: Discover | E3: Active | F3: 2172 | G3: EG01-EG02-EG03 | H3: the.peace20006@gmail.com | I3: 01067579926
A4: رحاب حمدي | B4: 838198456425 | C4: Lower Primary | D4: Discover | E4: Active | F4: 2171 | G4: EG01-EG02-EG03 | H4: rehab533@gmail.com | I4: 01019577994
A5: نرمين جلال | B5: 209148542918 | C5: Lower Primary | D5: Discover | E5: Active | F5: 2191 | G5: EG01-EG02-EG03-EG04-EG05 | H5: norenosman11@yahoo.com | I5: 01285292060
A6: ندى عبد النبي | B6: 105150134960 | C6: Lower Primary | D6: Discover | E6: Active | F6: 2212 | G6: EG01-EG02-EG03 | H6: nadalisaid46@gmail.com | I6: 01273190435
A7: مروة مجدي | B7: 189108478931 | C7: Lower Primary | D7: Discover | E7: Active | F7: 2443 | G7: EG01-EG02-EG03 | H7: jodyy2007@gmail.com | I7: 01091927577
A8: يارا سلطان | B8: 919170561064 | C8: Lower Primary | D8: Discover | E8: Active | F8: 2561 | G8: EG01-EG02-EG03 | H8: ywael044@gmail.com | I8: 01271833101
A9: أسماء الحسيني | B9: 623157516497 | C9: Lower Primary | D9: Discover | E9: Active | F9: 2580 | G9: EG01-EG02-EG03 | H9: elhosseinyasmaa@gmail.com | I9: 01006995563
A10: دعاء مصطفى | B10: 634163474745 | C10: Lower Primary | D10: Discover | E10: Active | F10: 2722 | G10: EG01-EG02-EG03-EG04-EG05-EG06 | H10: doaamostafaalis@gmail.com | I10: 01012291825
A11: مونيكا إدوارد | B11: 194190610534 | C11: Lower Primary | D11: Discover | E11: Backup | F11: 2757 | G11: EG01-EG02-EG03-EG04 | H11: moneyedward37@gmail.com | I11: 01277626560
A12: دنيا فاروق | B12: 148126371346 | C12: Lower Primary | D12: Discover | E12: Backup | F12: 2745 | G12: EG01-EG02-EG03 | H12: doniafarouk2811@gmail.com | I12: 01201302647
A13: إيريني عاطف | B13: 530189784630 | C13: Lower Primary | D13: English | E13: Active | F13: 2003 | G13: EG01-EG02-EG03-EG04-EG05 | H13: erineyatef@gmail.com | I13: 01211816220
A14: هبة عبد الحميد | B14: 603187625747 | C14: Lower Primary | D14: English | E14: Active | F14: 2103 | H14: heba.abdelhameed99@gmail.com | I14: 01126571109
A15: مها عبد الله | B15: 865121843486 | C15: Lower Primary | D15: English | E15: Active | F15: 2244 | H15: mahahimony@gmail.com | I15: 01156615561
A16: ميرا هشام | B16: 758108752769 | C16: Lower Primary | D16: English | E16: Active | F16: 2337 | H16: merahesham2000@gmail.com | I16: 01027391210
A17: نوران أسامة | B17: 426167021594 | C17: Lower Primary | D17: English | E17: Active | F17: 2519 | G17: EG01-EG02-EG03-EG04 | H17: nouranyl64@gmail.com | I17: 01010594459
A18: إسراء علاء | B18: 915139613231 | C18: Lower Primary | D18: English | E18: Backup | F18: 2422 | G18: EG01-EG02-EG03-EG04-EG05-EG06-EG07 | H18: esraalaa25@gmail.com | I18: 01091311114
A19: سارة جرجس | B19: 598135839671 | C19: Lower Primary | D19: English | E19: Active | F19: 2493 | G19: EG01-EG02-EG03-EG04-EG05 | H19: aueed.eteachers@gmail.com | I19: 01270819064
A20: ندى شريف | B20: 695139708380 | C20: Lower Primary | D20: English | E20: Active | F20: 2614 | G20: EG01-EG02-EG03-EG04-EG05 | H20: nadasherif1007@gmail.com
A21: أسماء حمزة | B21: 967160462696 | C21: Lower Primary | D21: English | E21: Active | F21: 2643 | G21: EG01-EG02 | H21: somahamza27@gmail.com
A22: شاهندة عبد العزيز | B22: 135178965350 | C22: Lower Primary | D22: English | E22: Inactive | F22: 2642 | G22: EG01-EG02 | H22: shahendaabdulaziz98@gmail.com | I22: 01004298923
A23: جيهان سمير | B23: 930131871381 | C23: Lower Primary | D23: English | E23: Active | F23: 2715 | G23: EG01-EG02-EG03-EG04-5 | H23: mrsgehan94@gmail.com | I23: 1013586544
A24: ريهام هريدي | B24: 208148393089 | C24: Lower Primary | D24: English | E24: Active | F24: 2695 | G24: EG01-EG02 | H24: reham.haridy17@gmail.com | I24: 01126620688
A25: ندى علي | B25: 406159296081 | C25: Lower Primary | D25: English | E25: Active | F25: 2730 | G25: EG01-EG02-EG03-EG04 | H25: nadaaly58@gmail.com | I25: 01275735695
A26: مارينا عماد | B26: 586170564150 | C26: Lower Primary | D26: English | E26: Active | F26: 2629 | G26: EG01-EG02-EG03-EG04 | H26: marinaemad4922@gmail.com | I26: 01210882072
A27: ماريام أشرف | B27: 450190591429 | C27: Lower Primary | D27: English | E27: Active | F27: 2781 | G27: EG01-EG02-EG03-EG04 | H27: ashrfmaryam557@gmail.com
A28: إيمان جلال | B28: 618168909236 | C28: Lower Primary | D28: English | E28: Active | F28: 2784 | G28: EG01-EG02-EG03-EG04-EG05-EG06 | H28: galaleman21@yahoo.com | I28: 01276133970
A29: نهى لطفي | B29: 729171317072 | C29: Lower Primary | D29: English | E29: Active | F29: 2771 | G29: EG01-EG02-EG03-EG04-EG05-EG06 | H29: nohalotfy33@gmail.com | I29: 01271850094
A30: صفا عادل | B30: 898178084762 | C30: Lower Primary | D30: English | E30: Backup | F30: 2783 | G30: EG01-EG02-EG03-EG04-EG05-EG06 | H30: safaadel499@gmail.com
A31: نجوى بدوي | B31: 193161234392 | C31: Lower Primary | D31: English | E31: Inactive | F31: 2779 | G31: EG01-EG02-EG03 | H31: nosamohamed000@gmail.com
A32: شاهنده محمد | B32: 439182479634 | C32: Lower Primary | D32: English | E32: Active | F32: 2807 | G32: EG01-EG02-EG03-EG04 | H32: shahendamohammad3@gmail.com | I32: 01223315390
A33: أسماء أشرف | B33: 363152838573 | C33: Lower Primary | D33: Mathematics | E33: Active | F33: 2310 | H33: asmaaashraf.aa@gmail.com | I33: 01015511375
A34: آية صبحي | B34: 628128564178 | C34: Lower Primary | D34: Mathematics | E34: Active | F34: 2290 | H34: ayasobhy2014@gmail.com | I34: 01096896433
A35: نورهان هاني | B35: 832181306187 | C35: Lower Primary | D35: Mathematics | E35: Backup | F35: 2436 | G35: EG01-EG02-EG03-EG04-EG05-EG06 | H35: nourhan.hany.amer.1992@gmail.com | I35: 01023766623
A36: آية فتحي | B36: 617181867475 | C36: Lower Primary | D36: Mathematics | E36: Active | F36: 2428 | G36: EG01-EG02-EG03-EG04-EG05-EG06 | H36: ayafathy1020@gmail.com | I36: 01025755518//01507075518
A37: نورهان ياسر | B37: 957197456092 | C37: Lower Primary | D37: Mathematics | E37: Active | F37: 2427 | G37: EG01-EG02-EG03 | H37: nourhanyasser1999184@gmail.com | I37: 01110620513
A38: إيمان رمضان | B38: 896191427156 | C38: Lower Primary | D38: Mathematics | E38: Active | F38: 2440 | G38: EG01-EG02-EG03 | H38: emanali8134@gmail.com | I38: 01282166883
A39: آية عادل | B39: 304149687570 | C39: Lower Primary | D39: Mathematics | E39: Active | F39: 2454 | G39: EG01-EG02-EG03 | H39: aya963539@gmail.com | I39: 01064460758
A40: دينا رضوان | B40: 590135797239 | C40: Lower Primary | D40: Mathematics | E40: Active | F40: 2447 | G40: EG01-EG02-EG03-EG04-EG05 | H40: dinaradwan109@gmail.com | I40: 01144211463
...

Sheet Sheet2
A1: =IFERROR(__xludf.DUMMYFUNCTION("IMPORTRANGE(""https://docs.google.com/spreadsheets/d/196Silsrf5-pGVgMAh12IsxqLLk10J-5WvEmb-v-qEgc/edit?pli=1&gid=91105518#gid=91105518"", ""Tutors Data!B:B"")"),"Tutor Name") -> Tutor Name | B1: =IFERROR(__xludf.DUMMYFUNCTION("IMPORTRANGE(""https://docs.google.com/spreadsheets/d/196Silsrf5-pGVgMAh12IsxqLLk10J-5WvEmb-v-qEgc/edit?pli=1&gid=91105518#gid=91105518"", ""Tutors Data!a:a"")"),"Tutor ID") -> Tutor ID | C1: =IFERROR(__xludf.DUMMYFUNCTION("IMPORTRANGE(""https://docs.google.com/spreadsheets/d/196Silsrf5-pGVgMAh12IsxqLLk10J-5WvEmb-v-qEgc/edit?pli=1&gid=91105518#gid=91105518"", ""Tutors Data!B:B"")"),"Tutor Name") -> Tutor Name | D1: =IFERROR(__xludf.DUMMYFUNCTION("IMPORTRANGE(""https://docs.google.com/spreadsheets/d/196Silsrf5-pGVgMAh12IsxqLLk10J-5WvEmb-v-qEgc/edit?pli=1&gid=91105518#gid=91105518"", ""Tutors Data!d:d"")"),"HR ID") -> HR ID | E1: =IFERROR(__xludf.DUMMYFUNCTION("IMPORTRANGE(""https://docs.google.com/spreadsheets/d/196Silsrf5-pGVgMAh12IsxqLLk10J-5WvEmb-v-qEgc/edit?pli=1&gid=91105518#gid=91105518"", ""Tutors Data!g:g"")"),"Stage") -> Stage | F1: =IFERROR(__xludf.DUMMYFUNCTION("IMPORTRANGE(""https://docs.google.com/spreadsheets/d/196Silsrf5-pGVgMAh12IsxqLLk10J-5WvEmb-v-qEgc/edit?pli=1&gid=91105518#gid=91105518"", ""Tutors Data!h:i"")"),"email") -> email | G1: =IFERROR(__xludf.DUMMYFUNCTION("""COMPUTED_VALUE"""),"Mobile Number") -> Mobile Number
A2: =IFERROR(__xludf.DUMMYFUNCTION("""COMPUTED_VALUE"""),"أحمد حاتم") -> أحمد حاتم | B2: =IFERROR(__xludf.DUMMYFUNCTION("""COMPUTED_VALUE"""),179169073012) -> 179169073012 | C2: =IFERROR(__xludf.DUMMYFUNCTION("""COMPUTED_VALUE"""),"أحمد حاتم") -> أحمد حاتم | D2: =IFERROR(__xludf.DUMMYFUNCTION("""COMPUTED_VALUE"""),"888") -> 888 | F2: =IFERROR(__xludf.DUMMYFUNCTION("""COMPUTED_VALUE"""),"ahmed.hatem@nagwa.com") -> ahmed.hatem@nagwa.com | G2: =IFERROR(__xludf.DUMMYFUNCTION("""COMPUTED_VALUE"""),201156629949) -> 201156629949
A3: =IFERROR(__xludf.DUMMYFUNCTION("""COMPUTED_VALUE"""),"مازن جاد") -> مازن جاد | B3: =IFERROR(__xludf.DUMMYFUNCTION("""COMPUTED_VALUE"""),452123973904) -> 452123973904 | C3: =IFERROR(__xludf.DUMMYFUNCTION("""COMPUTED_VALUE"""),"مازن جاد") -> مازن جاد | D3: =IFERROR(__xludf.DUMMYFUNCTION("""COMPUTED_VALUE"""),"1330") -> 1330 | F3: =IFERROR(__xludf.DUMMYFUNCTION("""COMPUTED_VALUE"""),"s-mazenhafez@zewailcity.edu.eg") -> s-mazenhafez@zewailcity.edu.eg
A4: =IFERROR(__xludf.DUMMYFUNCTION("""COMPUTED_VALUE"""),"ربيع الدوحة") -> ربيع الدوحة | B4: =IFERROR(__xludf.DUMMYFUNCTION("""COMPUTED_VALUE"""),656179636850) -> 656179636850 | C4: =IFERROR(__xludf.DUMMYFUNCTION("""COMPUTED_VALUE"""),"ربيع الدوحة") -> ربيع الدوحة | D4: =IFERROR(__xludf.DUMMYFUNCTION("""COMPUTED_VALUE"""),"110") -> 110 | E4: =IFERROR(__xludf.DUMMYFUNCTION("""COMPUTED_VALUE"""),"EG07-EG08-EG09-EG10-EG11-EG12") -> EG07-EG08-EG09-EG10-EG11-EG12 | F4: =IFERROR(__xludf.DUMMYFUNCTION("""COMPUTED_VALUE"""),"rabeeelshaer1@gmail.com") -> rabeeelshaer1@gmail.com
A5: =IFERROR(__xludf.DUMMYFUNCTION("""COMPUTED_VALUE"""),"رضا جبريل") -> رضا جبريل | B5: =IFERROR(__xludf.DUMMYFUNCTION("""COMPUTED_VALUE"""),198159430149) -> 198159430149 | C5: =IFERROR(__xludf.DUMMYFUNCTION("""COMPUTED_VALUE"""),"رضا جبريل") -> رضا جبريل | D5: =IFERROR(__xludf.DUMMYFUNCTION("""COMPUTED_VALUE"""),"1083") -> 1083 | E5: =IFERROR(__xludf.DUMMYFUNCTION("""COMPUTED_VALUE"""),"EG10-EG11-EG12") -> EG10-EG11-EG12
A6: =IFERROR(__xludf.DUMMYFUNCTION("""COMPUTED_VALUE"""),"عبير فؤاد") -> عبير فؤاد | B6: =IFERROR(__xludf.DUMMYFUNCTION("""COMPUTED_VALUE"""),893170457017) -> 893170457017 | C6: =IFERROR(__xludf.DUMMYFUNCTION("""COMPUTED_VALUE"""),"عبير فؤاد") -> عبير فؤاد | D6: =IFERROR(__xludf.DUMMYFUNCTION("""COMPUTED_VALUE"""),"1245") -> 1245 | F6: =IFERROR(__xludf.DUMMYFUNCTION("""COMPUTED_VALUE"""),"abeer.fouad@nagwa.com") -> abeer.fouad@nagwa.com | G6: =IFERROR(__xludf.DUMMYFUNCTION("""COMPUTED_VALUE"""),201090406534) -> 201090406534
A7: =IFERROR(__xludf.DUMMYFUNCTION("""COMPUTED_VALUE"""),"عبد الله معين") -> عبد الله معين | B7: =IFERROR(__xludf.DUMMYFUNCTION("""COMPUTED_VALUE"""),130151805637) -> 130151805637 | C7: =IFERROR(__xludf.DUMMYFUNCTION("""COMPUTED_VALUE"""),"عبد الله معين") -> عبد الله معين | D7: =IFERROR(__xludf.DUMMYFUNCTION("""COMPUTED_VALUE"""),"145") -> 145 | E7: =IFERROR(__xludf.DUMMYFUNCTION("""COMPUTED_VALUE"""),"EG04-EG05-EG06-EG07-EG08-EG09-EG10-EG11-EG12") -> EG04-EG05-EG06-EG07-EG08-EG09-EG10-EG11-EG12 | F7: =IFERROR(__xludf.DUMMYFUNCTION("""COMPUTED_VALUE"""),"abdallah.moeenn@gmail.com") -> abdallah.moeenn@gmail.com
A8: =IFERROR(__xludf.DUMMYFUNCTION("""COMPUTED_VALUE"""),"محمد البدساوي") -> محمد البدساوي | B8: =IFERROR(__xludf.DUMMYFUNCTION("""COMPUTED_VALUE"""),143165762069) -> 143165762069 | C8: =IFERROR(__xludf.DUMMYFUNCTION("""COMPUTED_VALUE"""),"محمد البدساوي") -> محمد البدساوي | D8: =IFERROR(__xludf.DUMMYFUNCTION("""COMPUTED_VALUE"""),"737") -> 737 | E8: =IFERROR(__xludf.DUMMYFUNCTION("""COMPUTED_VALUE"""),"EG04-EG05-EG06-EG07-EG08-EG09-EG10-EG11-EG12") -> EG04-EG05-EG06-EG07-EG08-EG09-EG10-EG11-EG12 | F8: =IFERROR(__xludf.DUMMYFUNCTION("""COMPUTED_VALUE"""),"mohamed.eid@nagwa.com") -> mohamed.eid@nagwa.com
A9: =IFERROR(__xludf.DUMMYFUNCTION("""COMPUTED_VALUE"""),"محمد إسماعيل") -> محمد إسماعيل | B9: =IFERROR(__xludf.DUMMYFUNCTION("""COMPUTED_VALUE"""),906184953437) -> 906184953437 | C9: =IFERROR(__xludf.DUMMYFUNCTION("""COMPUTED_VALUE"""),"محمد إسماعيل") -> محمد إسماعيل | D9: =IFERROR(__xludf.DUMMYFUNCTION("""COMPUTED_VALUE"""),"1763") -> 1763 | F9: =IFERROR(__xludf.DUMMYFUNCTION("""COMPUTED_VALUE"""),"ismailm1989@gmail.com") -> ismailm1989@gmail.com | G9: =IFERROR(__xludf.DUMMYFUNCTION("""COMPUTED_VALUE"""),201129525491) -> 201129525491
A10: =IFERROR(__xludf.DUMMYFUNCTION("""COMPUTED_VALUE"""),"عمرو خطاب") -> عمرو خطاب | B10: =IFERROR(__xludf.DUMMYFUNCTION("""COMPUTED_VALUE"""),159150394389) -> 159150394389 | C10: =IFERROR(__xludf.DUMMYFUNCTION("""COMPUTED_VALUE"""),"عمرو خطاب") -> عمرو خطاب | D10: =IFERROR(__xludf.DUMMYFUNCTION("""COMPUTED_VALUE"""),"443") -> 443 | F10: =IFERROR(__xludf.DUMMYFUNCTION("""COMPUTED_VALUE"""),"amr.khattab@nagwa.com") -> amr.khattab@nagwa.com
A11: =IFERROR(__xludf.DUMMYFUNCTION("""COMPUTED_VALUE"""),"حسين مصطفى") -> حسين مصطفى | B11: =IFERROR(__xludf.DUMMYFUNCTION("""COMPUTED_VALUE"""),467134069813) -> 467134069813 | C11: =IFERROR(__xludf.DUMMYFUNCTION("""COMPUTED_VALUE"""),"حسين مصطفى") -> حسين مصطفى | D11: =IFERROR(__xludf.DUMMYFUNCTION("""COMPUTED_VALUE"""),"1127") -> 1127 | E11: =IFERROR(__xludf.DUMMYFUNCTION("""COMPUTED_VALUE"""),"EG04-EG05-EG06-EG07-EG08-EG09-EG10-EG11-EG12") -> EG04-EG05-EG06-EG07-EG08-EG09-EG10-EG11-EG12 | F11: =IFERROR(__xludf.DUMMYFUNCTION("""COMPUTED_VALUE"""),"hussein.mostafa@nagwa.com") -> hussein.mostafa@nagwa.com | G11: =IFERROR(__xludf.DUMMYFUNCTION("""COMPUTED_VALUE"""),201091050146) -> 201091050146
A12: =IFERROR(__xludf.DUMMYFUNCTION("""COMPUTED_VALUE"""),"علياء مكاوي") -> علياء مكاوي | B12: =IFERROR(__xludf.DUMMYFUNCTION("""COMPUTED_VALUE"""),615158327698) -> 615158327698 | C12: =IFERROR(__xludf.DUMMYFUNCTION("""COMPUTED_VALUE"""),"علياء مكاوي") -> علياء مكاوي | D12: =IFERROR(__xludf.DUMMYFUNCTION("""COMPUTED_VALUE"""),"1471") -> 1471 | E12: =IFERROR(__xludf.DUMMYFUNCTION("""COMPUTED_VALUE"""),"EG04-EG05-EG06-EG07-EG08-EG09") -> EG04-EG05-EG06-EG07-EG08-EG09 | F12: =IFERROR(__xludf.DUMMYFUNCTION("""COMPUTED_VALUE"""),"aliaa.makkawy@nagwa.com") -> aliaa.makkawy@nagwa.com | G12: =IFERROR(__xludf.DUMMYFUNCTION("""COMPUTED_VALUE"""),201063570903) -> 201063570903
A13: =IFERROR(__xludf.DUMMYFUNCTION("""COMPUTED_VALUE"""),"زينة الشيخ") -> زينة الشيخ | B13: =IFERROR(__xludf.DUMMYFUNCTION("""COMPUTED_VALUE"""),632164034291) -> 632164034291 | C13: =IFERROR(__xludf.DUMMYFUNCTION("""COMPUTED_VALUE"""),"زينة الشيخ") -> زينة الشيخ | D13: =IFERROR(__xludf.DUMMYFUNCTION("""COMPUTED_VALUE"""),"1004") -> 1004 | E13: =IFERROR(__xludf.DUMMYFUNCTION("""COMPUTED_VALUE"""),"EG04-EG05-EG06-EG07-EG08-EG09") -> EG04-EG05-EG06-EG07-EG08-EG09 | F13: =IFERROR(__xludf.DUMMYFUNCTION("""COMPUTED_VALUE"""),"zeina.elsheikh@nagwa.com") -> zeina.elsheikh@nagwa.com | G13: =IFERROR(__xludf.DUMMYFUNCTION("""COMPUTED_VALUE"""),"01097890222") -> 01097890222
A14: =IFERROR(__xludf.DUMMYFUNCTION("""COMPUTED_VALUE"""),"إسلام محمد") -> إسلام محمد | B14: =IFERROR(__xludf.DUMMYFUNCTION("""COMPUTED_VALUE"""),170181505929) -> 170181505929 | C14: =IFERROR(__xludf.DUMMYFUNCTION("""COMPUTED_VALUE"""),"إسلام محمد") -> إسلام محمد | D14: =IFERROR(__xludf.DUMMYFUNCTION("""COMPUTED_VALUE"""),"1647") -> 1647 | F14: =IFERROR(__xludf.DUMMYFUNCTION("""COMPUTED_VALUE"""),"eslam.mohamed@nagwa.com") -> eslam.mohamed@nagwa.com | G14: =IFERROR(__xludf.DUMMYFUNCTION("""COMPUTED_VALUE"""),"01097158020") -> 01097158020
A15: =IFERROR(__xludf.DUMMYFUNCTION("""COMPUTED_VALUE"""),"محمد رفعت") -> محمد رفعت | B15: =IFERROR(__xludf.DUMMYFUNCTION("""COMPUTED_VALUE"""),698108096794) -> 698108096794 | C15: =IFERROR(__xludf.DUMMYFUNCTION("""COMPUTED_VALUE"""),"محمد رفعت") -> محمد رفعت | D15: =IFERROR(__xludf.DUMMYFUNCTION("""COMPUTED_VALUE"""),"1776") -> 1776 | F15: =IFERROR(__xludf.DUMMYFUNCTION("""COMPUTED_VALUE"""),"seniormaths25@gmail.com") -> seniormaths25@gmail.com | G15: =IFERROR(__xludf.DUMMYFUNCTION("""COMPUTED_VALUE"""),"01129242524") -> 01129242524
A16: =IFERROR(__xludf.DUMMYFUNCTION("""COMPUTED_VALUE"""),"نورهان حشاد") -> نورهان حشاد | B16: =IFERROR(__xludf.DUMMYFUNCTION("""COMPUTED_VALUE"""),408124082075) -> 408124082075 | C16: =IFERROR(__xludf.DUMMYFUNCTION("""COMPUTED_VALUE"""),"نورهان حشاد") -> نورهان حشاد | D16: =IFERROR(__xludf.DUMMYFUNCTION("""COMPUTED_VALUE"""),1363) -> 1363 | F16: =IFERROR(__xludf.DUMMYFUNCTION("""COMPUTED_VALUE"""),"nourhan.hashad@nagwa.com") -> nourhan.hashad@nagwa.com | G16: =IFERROR(__xludf.DUMMYFUNCTION("""COMPUTED_VALUE"""),201112094005) -> 201112094005
A17: =IFERROR(__xludf.DUMMYFUNCTION("""COMPUTED_VALUE"""),"أحمد عماد") -> أحمد عماد | B17: =IFERROR(__xludf.DUMMYFUNCTION("""COMPUTED_VALUE"""),352134305787) -> 352134305787 | C17: =IFERROR(__xludf.DUMMYFUNCTION("""COMPUTED_VALUE"""),"أحمد عماد") -> أحمد عماد | D17: =IFERROR(__xludf.DUMMYFUNCTION("""COMPUTED_VALUE"""),"1212") -> 1212
A18: =IFERROR(__xludf.DUMMYFUNCTION("""COMPUTED_VALUE"""),"شادي خالد") -> شادي خالد | B18: =IFERROR(__xludf.DUMMYFUNCTION("""COMPUTED_VALUE"""),648193010591) -> 648193010591 | C18: =IFERROR(__xludf.DUMMYFUNCTION("""COMPUTED_VALUE"""),"شادي خالد") -> شادي خالد | D18: =IFERROR(__xludf.DUMMYFUNCTION("""COMPUTED_VALUE"""),"1087") -> 1087 | E18: =IFERROR(__xludf.DUMMYFUNCTION("""COMPUTED_VALUE"""),"EG10-EG11-G12") -> EG10-EG11-G12 | F18: =IFERROR(__xludf.DUMMYFUNCTION("""COMPUTED_VALUE"""),"shady.donia@nagwa.com") -> shady.donia@nagwa.com | G18: =IFERROR(__xludf.DUMMYFUNCTION("""COMPUTED_VALUE"""),201119117049) -> 201119117049
A19: =IFERROR(__xludf.DUMMYFUNCTION("""COMPUTED_VALUE"""),"ملك عليوي") -> ملك عليوي | B19: =IFERROR(__xludf.DUMMYFUNCTION("""COMPUTED_VALUE"""),535169041274) -> 535169041274 | C19: =IFERROR(__xludf.DUMMYFUNCTION("""COMPUTED_VALUE"""),"ملك عليوي") -> ملك عليوي | D19: =IFERROR(__xludf.DUMMYFUNCTION("""COMPUTED_VALUE"""),"1490") -> 1490 | E19: =IFERROR(__xludf.DUMMYFUNCTION("""COMPUTED_VALUE"""),"EG10-EG11") -> EG10-EG11 | F19: =IFERROR(__xludf.DUMMYFUNCTION("""COMPUTED_VALUE"""),"malak.maliwy@gmail.com") -> malak.maliwy@gmail.com
A20: =IFERROR(__xludf.DUMMYFUNCTION("""COMPUTED_VALUE"""),"عمرو خليل") -> عمرو خليل | B20: =IFERROR(__xludf.DUMMYFUNCTION("""COMPUTED_VALUE"""),895194823203) -> 895194823203 | C20: =IFERROR(__xludf.DUMMYFUNCTION("""COMPUTED_VALUE"""),"عمرو خليل") -> عمرو خليل | D20: =IFERROR(__xludf.DUMMYFUNCTION("""COMPUTED_VALUE"""),"1779") -> 1779 | F20: =IFERROR(__xludf.DUMMYFUNCTION("""COMPUTED_VALUE"""),"eng.amrkhalil2014@gmail.com") -> eng.amrkhalil2014@gmail.com | G20: =IFERROR(__xludf.DUMMYFUNCTION("""COMPUTED_VALUE"""),201146486750) -> 201146486750
A21: =IFERROR(__xludf.DUMMYFUNCTION("""COMPUTED_VALUE"""),"أحمد هنداوي") -> أحمد هنداوي | B21: =IFERROR(__xludf.DUMMYFUNCTION("""COMPUTED_VALUE"""),238197230360) -> 238197230360 | C21: =IFERROR(__xludf.DUMMYFUNCTION("""COMPUTED_VALUE"""),"أحمد هنداوي") -> أحمد هنداوي | D21: =IFERROR(__xludf.DUMMYFUNCTION("""COMPUTED_VALUE"""),"#N/A") -> #N/A | F21: =IFERROR(__xludf.DUMMYFUNCTION("""COMPUTED_VALUE"""),"ahmed.hindawi@nagwa.com") -> ahmed.hindawi@nagwa.com
A22: =IFERROR(__xludf.DUMMYFUNCTION("""COMPUTED_VALUE"""),"عصام عمر") -> عصام عمر | B22: =IFERROR(__xludf.DUMMYFUNCTION("""COMPUTED_VALUE"""),142159241646) -> 142159241646 | C22: =IFERROR(__xludf.DUMMYFUNCTION("""COMPUTED_VALUE"""),"عصام عمر") -> عصام عمر | D22: =IFERROR(__xludf.DUMMYFUNCTION("""COMPUTED_VALUE"""),"1534") -> 1534 | F22: =IFERROR(__xludf.DUMMYFUNCTION("""COMPUTED_VALUE"""),"essam.omar@nagwa.com") -> essam.omar@nagwa.com | G22: =IFERROR(__xludf.DUMMYFUNCTION("""COMPUTED_VALUE"""),201113618461) -> 201113618461
A23: =IFERROR(__xludf.DUMMYFUNCTION("""COMPUTED_VALUE"""),"محمد رمضان") -> محمد رمضان | B23: =IFERROR(__xludf.DUMMYFUNCTION("""COMPUTED_VALUE"""),940182090410) -> 940182090410 | C23: =IFERROR(__xludf.DUMMYFUNCTION("""COMPUTED_VALUE"""),"محمد رمضان") -> محمد رمضان | D23: =IFERROR(__xludf.DUMMYFUNCTION("""COMPUTED_VALUE"""),"575") -> 575 | F23: =IFERROR(__xludf.DUMMYFUNCTION("""COMPUTED_VALUE"""),"mohammed.elsayed.ramadan@nagwa.com") -> mohammed.elsayed.ramadan@nagwa.com | G23: =IFERROR(__xludf.DUMMYFUNCTION("""COMPUTED_VALUE"""),201025475475) -> 201025475475
A24: =IFERROR(__xludf.DUMMYFUNCTION("""COMPUTED_VALUE"""),"محمد إمام") -> محمد إمام | B24: =IFERROR(__xludf.DUMMYFUNCTION("""COMPUTED_VALUE"""),913169734907) -> 913169734907 | C24: =IFERROR(__xludf.DUMMYFUNCTION("""COMPUTED_VALUE"""),"محمد إمام") -> محمد إمام | D24: =IFERROR(__xludf.DUMMYFUNCTION("""COMPUTED_VALUE"""),"1759") -> 1759 | E24: =IFERROR(__xludf.DUMMYFUNCTION("""COMPUTED_VALUE"""),"EG10-EG11-G12") -> EG10-EG11-G12
A25: =IFERROR(__xludf.DUMMYFUNCTION("""COMPUTED_VALUE"""),"أحمد ياقوت") -> أحمد ياقوت | B25: =IFERROR(__xludf.DUMMYFUNCTION("""COMPUTED_VALUE"""),284105320408) -> 284105320408 | C25: =IFERROR(__xludf.DUMMYFUNCTION("""COMPUTED_VALUE"""),"أحمد ياقوت") -> أحمد ياقوت | D25: =IFERROR(__xludf.DUMMYFUNCTION("""COMPUTED_VALUE"""),"1757") -> 1757 | E25: =IFERROR(__xludf.DUMMYFUNCTION("""COMPUTED_VALUE"""),"لم يقبل نظام المحاسبة الجديد والتسجيلات فقرر الاستقالة، فيرجى التواصل معه وتنفيذ إجراءات إنهاء التعاقد وتسليم العهدة") -> لم يقبل نظام المحاسبة الجديد والتسجيلات فقرر الاستقالة، فيرجى التواصل معه وتنفيذ إجراءات إنهاء التعاقد وتسليم العهدة
A26: =IFERROR(__xludf.DUMMYFUNCTION("""COMPUTED_VALUE"""),"مريم حسين") -> مريم حسين | B26: =IFERROR(__xludf.DUMMYFUNCTION("""COMPUTED_VALUE"""),695180376491) -> 695180376491 | C26: =IFERROR(__xludf.DUMMYFUNCTION("""COMPUTED_VALUE"""),"مريم حسين") -> مريم حسين | D26: =IFERROR(__xludf.DUMMYFUNCTION("""COMPUTED_VALUE"""),"1758") -> 1758 | F26: =IFERROR(__xludf.DUMMYFUNCTION("""COMPUTED_VALUE"""),"mero.mro9@gmail.com") -> mero.mro9@gmail.com
A27: =IFERROR(__xludf.DUMMYFUNCTION("""COMPUTED_VALUE"""),"محمد منصور") -> محمد منصور | B27: =IFERROR(__xludf.DUMMYFUNCTION("""COMPUTED_VALUE"""),560135012165) -> 560135012165 | C27: =IFERROR(__xludf.DUMMYFUNCTION("""COMPUTED_VALUE"""),"محمد منصور") -> محمد منصور | D27: =IFERROR(__xludf.DUMMYFUNCTION("""COMPUTED_VALUE"""),"1760") -> 1760 | E27: =IFERROR(__xludf.DUMMYFUNCTION("""COMPUTED_VALUE"""),"EG10-EG11-G12") -> EG10-EG11-G12 | F27: =IFERROR(__xludf.DUMMYFUNCTION("""COMPUTED_VALUE"""),"mansourphy@gmail.com") -> mansourphy@gmail.com | G27: =IFERROR(__xludf.DUMMYFUNCTION("""COMPUTED_VALUE"""),201069555347) -> 201069555347
A28: =IFERROR(__xludf.DUMMYFUNCTION("""COMPUTED_VALUE"""),"محمود أبو المجد") -> محمود أبو المجد | B28: =IFERROR(__xludf.DUMMYFUNCTION("""COMPUTED_VALUE"""),279170497570) -> 279170497570 | C28: =IFERROR(__xludf.DUMMYFUNCTION("""COMPUTED_VALUE"""),"محمود أبو المجد") -> محمود أبو المجد | D28: =IFERROR(__xludf.DUMMYFUNCTION("""COMPUTED_VALUE"""),"1243") -> 1243 | E28: =IFERROR(__xludf.DUMMYFUNCTION("""COMPUTED_VALUE"""),"EG04-EG05-EG06-G7-جيولوجيا EG12") -> EG04-EG05-EG06-G7-جيولوجيا EG12 | F28: =IFERROR(__xludf.DUMMYFUNCTION("""COMPUTED_VALUE"""),"mahmoud.aboelmagd@nagwa.com") -> mahmoud.aboelmagd@nagwa.com
A29: =IFERROR(__xludf.DUMMYFUNCTION("""COMPUTED_VALUE"""),"أحمد عبد اللطيف") -> أحمد عبد اللطيف | B29: =IFERROR(__xludf.DUMMYFUNCTION("""COMPUTED_VALUE"""),624104658072) -> 624104658072 | C29: =IFERROR(__xludf.DUMMYFUNCTION("""COMPUTED_VALUE"""),"أحمد عبد اللطيف") -> أحمد عبد اللطيف | D29: =IFERROR(__xludf.DUMMYFUNCTION("""COMPUTED_VALUE"""),"1265") -> 1265 | F29: =IFERROR(__xludf.DUMMYFUNCTION("""COMPUTED_VALUE"""),"ahmed.abdellatif@nagwa.com") -> ahmed.abdellatif@nagwa.com | G29: =IFERROR(__xludf.DUMMYFUNCTION("""COMPUTED_VALUE"""),201018842229) -> 201018842229
A30: =IFERROR(__xludf.DUMMYFUNCTION("""COMPUTED_VALUE"""),"رامي فاروق") -> رامي فاروق | B30: =IFERROR(__xludf.DUMMYFUNCTION("""COMPUTED_VALUE"""),680190738426) -> 680190738426 | C30: =IFERROR(__xludf.DUMMYFUNCTION("""COMPUTED_VALUE"""),"رامي فاروق") -> رامي فاروق | D30: =IFERROR(__xludf.DUMMYFUNCTION("""COMPUTED_VALUE"""),"1766") -> 1766 | F30: =IFERROR(__xludf.DUMMYFUNCTION("""COMPUTED_VALUE"""),"ramyfarouk9333@gmail.com") -> ramyfarouk9333@gmail.com | G30: =IFERROR(__xludf.DUMMYFUNCTION("""COMPUTED_VALUE"""),"01224288238") -> 01224288238
A31: =IFERROR(__xludf.DUMMYFUNCTION("""COMPUTED_VALUE"""),"سما الإبراشي") -> سما الإبراشي | B31: =IFERROR(__xludf.DUMMYFUNCTION("""COMPUTED_VALUE"""),156154179702) -> 156154179702 | C31: =IFERROR(__xludf.DUMMYFUNCTION("""COMPUTED_VALUE"""),"سما الإبراشي") -> سما الإبراشي | D31: =IFERROR(__xludf.DUMMYFUNCTION("""COMPUTED_VALUE"""),"1777") -> 1777 | E31: =IFERROR(__xludf.DUMMYFUNCTION("""COMPUTED_VALUE"""),"EG10-EG11-G12") -> EG10-EG11-G12 | F31: =IFERROR(__xludf.DUMMYFUNCTION("""COMPUTED_VALUE"""),"sama.elberashy@gmail.com") -> sama.elberashy@gmail.com | G31: =IFERROR(__xludf.DUMMYFUNCTION("""COMPUTED_VALUE"""),201001344221) -> 201001344221
A32: =IFERROR(__xludf.DUMMYFUNCTION("""COMPUTED_VALUE"""),"مينا جاد") -> مينا جاد | B32: =IFERROR(__xludf.DUMMYFUNCTION("""COMPUTED_VALUE"""),846101762818) -> 846101762818 | C32: =IFERROR(__xludf.DUMMYFUNCTION("""COMPUTED_VALUE"""),"مينا جاد") -> مينا جاد | D32: =IFERROR(__xludf.DUMMYFUNCTION("""COMPUTED_VALUE"""),1781) -> 1781
A33: =IFERROR(__xludf.DUMMYFUNCTION("""COMPUTED_VALUE"""),"أحمد حسن") -> أحمد حسن | B33: =IFERROR(__xludf.DUMMYFUNCTION("""COMPUTED_VALUE"""),480103238452) -> 480103238452 | C33: =IFERROR(__xludf.DUMMYFUNCTION("""COMPUTED_VALUE"""),"أحمد حسن") -> أحمد حسن | D33: =IFERROR(__xludf.DUMMYFUNCTION("""COMPUTED_VALUE"""),"1762") -> 1762 | F33: =IFERROR(__xludf.DUMMYFUNCTION("""COMPUTED_VALUE"""),"ahmedhassan99967@gmail.com") -> ahmedhassan99967@gmail.com | G33: =IFERROR(__xludf.DUMMYFUNCTION("""COMPUTED_VALUE"""),201007787118) -> 201007787118
A34: =IFERROR(__xludf.DUMMYFUNCTION("""COMPUTED_VALUE"""),"جهاد بدر") -> جهاد بدر | B34: =IFERROR(__xludf.DUMMYFUNCTION("""COMPUTED_VALUE"""),524151240185) -> 524151240185 | C34: =IFERROR(__xludf.DUMMYFUNCTION("""COMPUTED_VALUE"""),"جهاد بدر") -> جهاد بدر | D34: =IFERROR(__xludf.DUMMYFUNCTION("""COMPUTED_VALUE"""),"1786") -> 1786 | F34: =IFERROR(__xludf.DUMMYFUNCTION("""COMPUTED_VALUE"""),"gehadbadr89@gmail.com") -> gehadbadr89@gmail.com | G34: =IFERROR(__xludf.DUMMYFUNCTION("""COMPUTED_VALUE"""),"01090297182") -> 01090297182
A35: =IFERROR(__xludf.DUMMYFUNCTION("""COMPUTED_VALUE"""),"طارق سليم") -> طارق سليم | B35: =IFERROR(__xludf.DUMMYFUNCTION("""COMPUTED_VALUE"""),379176206354) -> 379176206354 | C35: =IFERROR(__xludf.DUMMYFUNCTION("""COMPUTED_VALUE"""),"طارق سليم") -> طارق سليم | D35: =IFERROR(__xludf.DUMMYFUNCTION("""COMPUTED_VALUE"""),"1778") -> 1778 | F35: =IFERROR(__xludf.DUMMYFUNCTION("""COMPUTED_VALUE"""),"tareksleem606@gmail.com") -> tareksleem606@gmail.com | G35: =IFERROR(__xludf.DUMMYFUNCTION("""COMPUTED_VALUE"""),201001599199) -> 201001599199
A36: =IFERROR(__xludf.DUMMYFUNCTION("""COMPUTED_VALUE"""),"أحمد علاء") -> أحمد علاء | B36: =IFERROR(__xludf.DUMMYFUNCTION("""COMPUTED_VALUE"""),352179823813) -> 352179823813 | C36: =IFERROR(__xludf.DUMMYFUNCTION("""COMPUTED_VALUE"""),"أحمد علاء") -> أحمد علاء | D36: =IFERROR(__xludf.DUMMYFUNCTION("""COMPUTED_VALUE"""),"1765") -> 1765 | F36: =IFERROR(__xludf.DUMMYFUNCTION("""COMPUTED_VALUE"""),"aassllyyaa68@gmail.com") -> aassllyyaa68@gmail.com
A37: =IFERROR(__xludf.DUMMYFUNCTION("""COMPUTED_VALUE"""),"أحمد عاطف") -> أحمد عاطف | B37: =IFERROR(__xludf.DUMMYFUNCTION("""COMPUTED_VALUE"""),308137598241) -> 308137598241 | C37: =IFERROR(__xludf.DUMMYFUNCTION("""COMPUTED_VALUE"""),"أحمد عاطف") -> أحمد عاطف | D37: =IFERROR(__xludf.DUMMYFUNCTION("""COMPUTED_VALUE"""),"1775") -> 1775 | F37: =IFERROR(__xludf.DUMMYFUNCTION("""COMPUTED_VALUE"""),"ahmedatef386@gmail.com") -> ahmedatef386@gmail.com | G37: =IFERROR(__xludf.DUMMYFUNCTION("""COMPUTED_VALUE"""),201098614126) -> 201098614126
A38: =IFERROR(__xludf.DUMMYFUNCTION("""COMPUTED_VALUE"""),"محمد عصام") -> محمد عصام | B38: =IFERROR(__xludf.DUMMYFUNCTION("""COMPUTED_VALUE"""),592179807615) -> 592179807615 | C38: =IFERROR(__xludf.DUMMYFUNCTION("""COMPUTED_VALUE"""),"محمد عصام") -> محمد عصام | D38: =IFERROR(__xludf.DUMMYFUNCTION("""COMPUTED_VALUE"""),"1277") -> 1277 | E38: =IFERROR(__xludf.DUMMYFUNCTION("""COMPUTED_VALUE"""),"EG07-EG08-EG09") -> EG07-EG08-EG09 | F38: =IFERROR(__xludf.DUMMYFUNCTION("""COMPUTED_VALUE"""),"modares2525@gmail.com") -> modares2525@gmail.com | G38: =IFERROR(__xludf.DUMMYFUNCTION("""COMPUTED_VALUE"""),201116153885) -> 201116153885
A39: =IFERROR(__xludf.DUMMYFUNCTION("""COMPUTED_VALUE"""),"وائل سلطان") -> وائل سلطان | B39: =IFERROR(__xludf.DUMMYFUNCTION("""COMPUTED_VALUE"""),415194597216) -> 415194597216 | C39: =IFERROR(__xludf.DUMMYFUNCTION("""COMPUTED_VALUE"""),"وائل سلطان") -> وائل سلطان | D39: =IFERROR(__xludf.DUMMYFUNCTION("""COMPUTED_VALUE"""),"1787") -> 1787 | F39: =IFERROR(__xludf.DUMMYFUNCTION("""COMPUTED_VALUE"""),"abomahmoudsoultan@gmail.com") -> abomahmoudsoultan@gmail.com | G39: =IFERROR(__xludf.DUMMYFUNCTION("""COMPUTED_VALUE"""),"00201153335900") -> 00201153335900
A40: =IFERROR(__xludf.DUMMYFUNCTION("""COMPUTED_VALUE"""),"أندرو ثروت") -> أندرو ثروت | B40: =IFERROR(__xludf.DUMMYFUNCTION("""COMPUTED_VALUE"""),417127195646) -> 417127195646 | C40: =IFERROR(__xludf.DUMMYFUNCTION("""COMPUTED_VALUE"""),"أندرو ثروت") -> أندرو ثروت | D40: =IFERROR(__xludf.DUMMYFUNCTION("""COMPUTED_VALUE"""),"1788") -> 1788 | E40: =IFERROR(__xludf.DUMMYFUNCTION("""COMPUTED_VALUE"""),"EG07-EG08-EG09") -> EG07-EG08-EG09 | F40: =IFERROR(__xludf.DUMMYFUNCTION("""COMPUTED_VALUE"""),"andrewtharwatfikry@gmail.com") -> andrewtharwatfikry@gmail.com | G40: =IFERROR(__xludf.DUMMYFUNCTION("""COMPUTED_VALUE"""),"01205947696") -> 01205947696
...
